2024-12-21 09:36:18,982 - aiogram.dispatcher - INFO - Start polling
2024-12-21 09:36:19,023 - aiogram.dispatcher - INFO - Run polling for bot @dofgd345borbot id=7101171025 - 'bobr123'
2024-12-21 09:36:20,854 - aiogram.dispatcher - WARNING - Received SIGINT signal
2024-12-21 09:36:20,855 - aiogram.dispatcher - INFO - Polling stopped for bot @dofgd345borbot id=7101171025 - 'bobr123'
2024-12-21 09:36:20,855 - aiogram.dispatcher - INFO - Polling stopped
2024-12-21 12:34:13,127 - aiogram.dispatcher - INFO - Start polling
2024-12-21 12:34:13,162 - aiogram.dispatcher - INFO - Run polling for bot @dofgd345borbot id=7101171025 - 'bobr123'
2024-12-21 12:34:43,379 - aiogram.event - INFO - Update id=166847769 is not handled. Duration 148 ms by bot id=7101171025
2024-12-21 12:34:43,379 - aiogram.event - ERROR - Cause exception while process update id=166847769 by bot id=7101171025
TypeError: create_message() missing 1 required positional argument: 'user'
Traceback (most recent call last):
  File "/home/bybr/Desktop/english_bot/.venv/lib/python3.12/site-packages/aiogram/dispatcher/dispatcher.py", line 309, in _process_update
    response = await self.feed_update(bot, update, **kwargs)
               ^^^^^^^^^^^^^^^^^^^^^^^^^^^^^^^^^^^^^^^^^^^^^
  File "/home/bybr/Desktop/english_bot/.venv/lib/python3.12/site-packages/aiogram/dispatcher/dispatcher.py", line 158, in feed_update
    response = await self.update.wrap_outer_middleware(
               ^^^^^^^^^^^^^^^^^^^^^^^^^^^^^^^^^^^^^^^^
  File "/home/bybr/Desktop/english_bot/.venv/lib/python3.12/site-packages/aiogram/dispatcher/middlewares/error.py", line 25, in __call__
    return await handler(event, data)
           ^^^^^^^^^^^^^^^^^^^^^^^^^^
  File "/home/bybr/Desktop/english_bot/.venv/lib/python3.12/site-packages/aiogram/dispatcher/middlewares/user_context.py", line 56, in __call__
    return await handler(event, data)
           ^^^^^^^^^^^^^^^^^^^^^^^^^^
  File "/home/bybr/Desktop/english_bot/.venv/lib/python3.12/site-packages/aiogram/fsm/middleware.py", line 42, in __call__
    return await handler(event, data)
           ^^^^^^^^^^^^^^^^^^^^^^^^^^
  File "/home/bybr/Desktop/english_bot/.venv/lib/python3.12/site-packages/aiogram/dispatcher/event/telegram.py", line 121, in trigger
    return await wrapped_inner(event, kwargs)
           ^^^^^^^^^^^^^^^^^^^^^^^^^^^^^^^^^^
  File "/home/bybr/Desktop/english_bot/.venv/lib/python3.12/site-packages/aiogram/dispatcher/event/handler.py", line 43, in call
    return await wrapped()
           ^^^^^^^^^^^^^^^
  File "/home/bybr/Desktop/english_bot/.venv/lib/python3.12/site-packages/aiogram/dispatcher/dispatcher.py", line 276, in _listen_update
    return await self.propagate_event(update_type=update_type, event=event, **kwargs)
           ^^^^^^^^^^^^^^^^^^^^^^^^^^^^^^^^^^^^^^^^^^^^^^^^^^^^^^^^^^^^^^^^^^^^^^^^^^
  File "/home/bybr/Desktop/english_bot/.venv/lib/python3.12/site-packages/aiogram/dispatcher/router.py", line 146, in propagate_event
    return await observer.wrap_outer_middleware(_wrapped, event=event, data=kwargs)
           ^^^^^^^^^^^^^^^^^^^^^^^^^^^^^^^^^^^^^^^^^^^^^^^^^^^^^^^^^^^^^^^^^^^^^^^^
  File "/home/bybr/Desktop/english_bot/.venv/lib/python3.12/site-packages/aiogram/dispatcher/router.py", line 141, in _wrapped
    return await self._propagate_event(
           ^^^^^^^^^^^^^^^^^^^^^^^^^^^^
  File "/home/bybr/Desktop/english_bot/.venv/lib/python3.12/site-packages/aiogram/dispatcher/router.py", line 174, in _propagate_event
    response = await router.propagate_event(update_type=update_type, event=event, **kwargs)
               ^^^^^^^^^^^^^^^^^^^^^^^^^^^^^^^^^^^^^^^^^^^^^^^^^^^^^^^^^^^^^^^^^^^^^^^^^^^^
  File "/home/bybr/Desktop/english_bot/.venv/lib/python3.12/site-packages/aiogram/dispatcher/router.py", line 146, in propagate_event
    return await observer.wrap_outer_middleware(_wrapped, event=event, data=kwargs)
           ^^^^^^^^^^^^^^^^^^^^^^^^^^^^^^^^^^^^^^^^^^^^^^^^^^^^^^^^^^^^^^^^^^^^^^^^
  File "/home/bybr/Desktop/english_bot/.venv/lib/python3.12/site-packages/aiogram/dispatcher/router.py", line 141, in _wrapped
    return await self._propagate_event(
           ^^^^^^^^^^^^^^^^^^^^^^^^^^^^
  File "/home/bybr/Desktop/english_bot/.venv/lib/python3.12/site-packages/aiogram/dispatcher/router.py", line 166, in _propagate_event
    response = await observer.trigger(event, **kwargs)
               ^^^^^^^^^^^^^^^^^^^^^^^^^^^^^^^^^^^^^^^
  File "/home/bybr/Desktop/english_bot/.venv/lib/python3.12/site-packages/aiogram/dispatcher/event/telegram.py", line 121, in trigger
    return await wrapped_inner(event, kwargs)
           ^^^^^^^^^^^^^^^^^^^^^^^^^^^^^^^^^^
  File "/home/bybr/Desktop/english_bot/telegram_bot/core/middlewares.py", line 23, in __call__
    return await handler(event, data)
           ^^^^^^^^^^^^^^^^^^^^^^^^^^
  File "/home/bybr/Desktop/english_bot/.venv/lib/python3.12/site-packages/aiogram/dispatcher/event/handler.py", line 43, in call
    return await wrapped()
           ^^^^^^^^^^^^^^^
  File "/home/bybr/Desktop/english_bot/telegram_bot/core/handlers.py", line 41, in handle_text_message
    obj_message, message_created = await db_request.create_message(obj_chat.pk, tg_user, message.text)
                                   ^^^^^^^^^^^^^^^^^^^^^^^^^^^^^^^^^^^^^^^^^^^^^^^^^^^^^^^^^^^^^^^^^^^
  File "/home/bybr/Desktop/english_bot/.venv/lib/python3.12/site-packages/asgiref/sync.py", line 468, in __call__
    ret = await asyncio.shield(exec_coro)
          ^^^^^^^^^^^^^^^^^^^^^^^^^^^^^^^
  File "/usr/lib/python3.12/concurrent/futures/thread.py", line 58, in run
    result = self.fn(*self.args, **self.kwargs)
             ^^^^^^^^^^^^^^^^^^^^^^^^^^^^^^^^^^
  File "/home/bybr/Desktop/english_bot/.venv/lib/python3.12/site-packages/asgiref/sync.py", line 522, in thread_handler
    return func(*args, **kwargs)
           ^^^^^^^^^^^^^^^^^^^^^
TypeError: create_message() missing 1 required positional argument: 'user'
2024-12-21 12:35:17,421 - aiogram.dispatcher - WARNING - Received SIGINT signal
2024-12-21 12:35:17,421 - aiogram.dispatcher - INFO - Polling stopped for bot @dofgd345borbot id=7101171025 - 'bobr123'
2024-12-21 12:35:17,422 - aiogram.dispatcher - INFO - Polling stopped
2024-12-21 12:35:20,393 - aiogram.dispatcher - INFO - Start polling
2024-12-21 12:35:20,430 - aiogram.dispatcher - INFO - Run polling for bot @dofgd345borbot id=7101171025 - 'bobr123'
2024-12-21 12:35:21,688 - telegram_bot.core.db_request - ERROR - Create message: Cannot assign "'345'": "TelegramUserAndAdminMessage.chat" must be a "TelegramUserAndAdminChat" instance.
2024-12-21 12:35:21,688 - aiogram.event - INFO - Update id=166847770 is not handled. Duration 6 ms by bot id=7101171025
2024-12-21 12:35:21,688 - aiogram.event - ERROR - Cause exception while process update id=166847770 by bot id=7101171025
AttributeError: 'NoneType' object has no attribute 'pk'
Traceback (most recent call last):
  File "/home/bybr/Desktop/english_bot/.venv/lib/python3.12/site-packages/aiogram/dispatcher/dispatcher.py", line 309, in _process_update
    response = await self.feed_update(bot, update, **kwargs)
               ^^^^^^^^^^^^^^^^^^^^^^^^^^^^^^^^^^^^^^^^^^^^^
  File "/home/bybr/Desktop/english_bot/.venv/lib/python3.12/site-packages/aiogram/dispatcher/dispatcher.py", line 158, in feed_update
    response = await self.update.wrap_outer_middleware(
               ^^^^^^^^^^^^^^^^^^^^^^^^^^^^^^^^^^^^^^^^
  File "/home/bybr/Desktop/english_bot/.venv/lib/python3.12/site-packages/aiogram/dispatcher/middlewares/error.py", line 25, in __call__
    return await handler(event, data)
           ^^^^^^^^^^^^^^^^^^^^^^^^^^
  File "/home/bybr/Desktop/english_bot/.venv/lib/python3.12/site-packages/aiogram/dispatcher/middlewares/user_context.py", line 56, in __call__
    return await handler(event, data)
           ^^^^^^^^^^^^^^^^^^^^^^^^^^
  File "/home/bybr/Desktop/english_bot/.venv/lib/python3.12/site-packages/aiogram/fsm/middleware.py", line 42, in __call__
    return await handler(event, data)
           ^^^^^^^^^^^^^^^^^^^^^^^^^^
  File "/home/bybr/Desktop/english_bot/.venv/lib/python3.12/site-packages/aiogram/dispatcher/event/telegram.py", line 121, in trigger
    return await wrapped_inner(event, kwargs)
           ^^^^^^^^^^^^^^^^^^^^^^^^^^^^^^^^^^
  File "/home/bybr/Desktop/english_bot/.venv/lib/python3.12/site-packages/aiogram/dispatcher/event/handler.py", line 43, in call
    return await wrapped()
           ^^^^^^^^^^^^^^^
  File "/home/bybr/Desktop/english_bot/.venv/lib/python3.12/site-packages/aiogram/dispatcher/dispatcher.py", line 276, in _listen_update
    return await self.propagate_event(update_type=update_type, event=event, **kwargs)
           ^^^^^^^^^^^^^^^^^^^^^^^^^^^^^^^^^^^^^^^^^^^^^^^^^^^^^^^^^^^^^^^^^^^^^^^^^^
  File "/home/bybr/Desktop/english_bot/.venv/lib/python3.12/site-packages/aiogram/dispatcher/router.py", line 146, in propagate_event
    return await observer.wrap_outer_middleware(_wrapped, event=event, data=kwargs)
           ^^^^^^^^^^^^^^^^^^^^^^^^^^^^^^^^^^^^^^^^^^^^^^^^^^^^^^^^^^^^^^^^^^^^^^^^
  File "/home/bybr/Desktop/english_bot/.venv/lib/python3.12/site-packages/aiogram/dispatcher/router.py", line 141, in _wrapped
    return await self._propagate_event(
           ^^^^^^^^^^^^^^^^^^^^^^^^^^^^
  File "/home/bybr/Desktop/english_bot/.venv/lib/python3.12/site-packages/aiogram/dispatcher/router.py", line 174, in _propagate_event
    response = await router.propagate_event(update_type=update_type, event=event, **kwargs)
               ^^^^^^^^^^^^^^^^^^^^^^^^^^^^^^^^^^^^^^^^^^^^^^^^^^^^^^^^^^^^^^^^^^^^^^^^^^^^
  File "/home/bybr/Desktop/english_bot/.venv/lib/python3.12/site-packages/aiogram/dispatcher/router.py", line 146, in propagate_event
    return await observer.wrap_outer_middleware(_wrapped, event=event, data=kwargs)
           ^^^^^^^^^^^^^^^^^^^^^^^^^^^^^^^^^^^^^^^^^^^^^^^^^^^^^^^^^^^^^^^^^^^^^^^^
  File "/home/bybr/Desktop/english_bot/.venv/lib/python3.12/site-packages/aiogram/dispatcher/router.py", line 141, in _wrapped
    return await self._propagate_event(
           ^^^^^^^^^^^^^^^^^^^^^^^^^^^^
  File "/home/bybr/Desktop/english_bot/.venv/lib/python3.12/site-packages/aiogram/dispatcher/router.py", line 166, in _propagate_event
    response = await observer.trigger(event, **kwargs)
               ^^^^^^^^^^^^^^^^^^^^^^^^^^^^^^^^^^^^^^^
  File "/home/bybr/Desktop/english_bot/.venv/lib/python3.12/site-packages/aiogram/dispatcher/event/telegram.py", line 121, in trigger
    return await wrapped_inner(event, kwargs)
           ^^^^^^^^^^^^^^^^^^^^^^^^^^^^^^^^^^
  File "/home/bybr/Desktop/english_bot/telegram_bot/core/middlewares.py", line 23, in __call__
    return await handler(event, data)
           ^^^^^^^^^^^^^^^^^^^^^^^^^^
  File "/home/bybr/Desktop/english_bot/.venv/lib/python3.12/site-packages/aiogram/dispatcher/event/handler.py", line 43, in call
    return await wrapped()
           ^^^^^^^^^^^^^^^
  File "/home/bybr/Desktop/english_bot/telegram_bot/core/handlers.py", line 42, in handle_text_message
    socket_result = await send_to_websocket(obj_chat.pk, obj_message.pk, message.text)
                                                         ^^^^^^^^^^^^^^
AttributeError: 'NoneType' object has no attribute 'pk'
2024-12-21 12:36:18,997 - aiogram.dispatcher - WARNING - Received SIGINT signal
2024-12-21 12:36:18,998 - aiogram.dispatcher - INFO - Polling stopped for bot @dofgd345borbot id=7101171025 - 'bobr123'
2024-12-21 12:36:18,998 - aiogram.dispatcher - INFO - Polling stopped
2024-12-21 12:36:21,683 - aiogram.dispatcher - INFO - Start polling
2024-12-21 12:36:21,723 - aiogram.dispatcher - INFO - Run polling for bot @dofgd345borbot id=7101171025 - 'bobr123'
2024-12-21 12:36:22,498 - telegram_bot.core.db_request - ERROR - Create message: Cannot assign "'345'": "TelegramUserAndAdminMessage.chat" must be a "TelegramUserAndAdminChat" instance.
2024-12-21 12:36:22,663 - aiogram.event - INFO - Update id=166847771 is handled. Duration 171 ms by bot id=7101171025
2024-12-21 12:37:00,691 - aiogram.dispatcher - WARNING - Received SIGINT signal
2024-12-21 12:37:00,692 - aiogram.dispatcher - INFO - Polling stopped for bot @dofgd345borbot id=7101171025 - 'bobr123'
2024-12-21 12:37:00,692 - aiogram.dispatcher - INFO - Polling stopped
2024-12-21 12:37:03,529 - aiogram.dispatcher - INFO - Start polling
2024-12-21 12:37:03,587 - aiogram.dispatcher - INFO - Run polling for bot @dofgd345borbot id=7101171025 - 'bobr123'
2024-12-21 12:37:04,369 - telegram_bot.core.db_request - ERROR - Create message: Cannot assign "'234'": "TelegramUserAndAdminMessage.chat" must be a "TelegramUserAndAdminChat" instance.
2024-12-21 12:37:04,576 - aiogram.event - INFO - Update id=166847772 is handled. Duration 214 ms by bot id=7101171025
2024-12-21 12:37:21,571 - aiogram.dispatcher - WARNING - Received SIGINT signal
2024-12-21 12:37:21,572 - aiogram.dispatcher - INFO - Polling stopped for bot @dofgd345borbot id=7101171025 - 'bobr123'
2024-12-21 12:37:21,572 - aiogram.dispatcher - INFO - Polling stopped
2024-12-21 12:37:25,550 - aiogram.dispatcher - INFO - Start polling
2024-12-21 12:37:25,586 - aiogram.dispatcher - INFO - Run polling for bot @dofgd345borbot id=7101171025 - 'bobr123'
2024-12-21 12:37:26,345 - telegram_bot.core.db_request - ERROR - Create message: Cannot assign "<TelegramUser: Telegram volody015>": "TelegramUserAndAdminMessage.chat" must be a "TelegramUserAndAdminChat" instance.
2024-12-21 12:37:26,505 - aiogram.event - INFO - Update id=166847773 is handled. Duration 166 ms by bot id=7101171025
2024-12-21 12:37:56,603 - aiogram.dispatcher - WARNING - Received SIGINT signal
2024-12-21 12:37:56,603 - aiogram.dispatcher - INFO - Polling stopped for bot @dofgd345borbot id=7101171025 - 'bobr123'
2024-12-21 12:37:56,603 - aiogram.dispatcher - INFO - Polling stopped
2024-12-21 12:37:59,391 - aiogram.dispatcher - INFO - Start polling
2024-12-21 12:37:59,426 - aiogram.dispatcher - INFO - Run polling for bot @dofgd345borbot id=7101171025 - 'bobr123'
2024-12-21 12:38:00,255 - telegram_bot.core.db_request - ERROR - Create message: Cannot assign "<TelegramUser: Telegram volody015>": "TelegramUserAndAdminMessage.sender" must be a "CustomUser" instance.
2024-12-21 12:38:00,407 - aiogram.event - INFO - Update id=166847774 is handled. Duration 159 ms by bot id=7101171025
2024-12-21 12:40:19,521 - aiogram.dispatcher - WARNING - Received SIGINT signal
2024-12-21 12:40:19,521 - aiogram.dispatcher - INFO - Polling stopped for bot @dofgd345borbot id=7101171025 - 'bobr123'
2024-12-21 12:40:19,521 - aiogram.dispatcher - INFO - Polling stopped
2024-12-21 12:41:52,675 - aiogram.dispatcher - INFO - Start polling
2024-12-21 12:41:52,713 - aiogram.dispatcher - INFO - Run polling for bot @dofgd345borbot id=7101171025 - 'bobr123'
2024-12-21 12:41:53,780 - telegram_bot.core.websocket_request - INFO - Message sent to websocket: 1 / 1 / 234
2024-12-21 12:41:53,915 - aiogram.event - INFO - Update id=166847775 is handled. Duration 151 ms by bot id=7101171025
2024-12-21 13:13:04,619 - aiogram.dispatcher - WARNING - Received SIGINT signal
2024-12-21 13:13:04,620 - aiogram.dispatcher - INFO - Polling stopped for bot @dofgd345borbot id=7101171025 - 'bobr123'
2024-12-21 13:13:04,620 - aiogram.dispatcher - INFO - Polling stopped
2024-12-21 13:13:07,519 - aiogram.dispatcher - INFO - Start polling
2024-12-21 13:13:07,558 - aiogram.dispatcher - INFO - Run polling for bot @dofgd345borbot id=7101171025 - 'bobr123'
2024-12-21 13:13:08,704 - telegram_bot.core.db_request - ERROR - Create message: module 'datetime' has no attribute 'utcnow'
2024-12-21 13:13:09,215 - aiogram.event - INFO - Update id=166847776 is handled. Duration 517 ms by bot id=7101171025
2024-12-21 13:13:41,451 - aiogram.dispatcher - WARNING - Received SIGINT signal
2024-12-21 13:13:41,452 - aiogram.dispatcher - INFO - Polling stopped for bot @dofgd345borbot id=7101171025 - 'bobr123'
2024-12-21 13:13:41,452 - aiogram.dispatcher - INFO - Polling stopped
2024-12-21 13:13:44,367 - aiogram.dispatcher - INFO - Start polling
2024-12-21 13:13:44,443 - aiogram.dispatcher - INFO - Run polling for bot @dofgd345borbot id=7101171025 - 'bobr123'
2024-12-21 13:13:46,457 - telegram_bot.core.db_request - ERROR - Create message: 'dict' object has no attribute 'append'
2024-12-21 13:13:46,626 - aiogram.event - INFO - Update id=166847777 is handled. Duration 175 ms by bot id=7101171025
2024-12-21 13:14:02,595 - aiogram.dispatcher - WARNING - Received SIGINT signal
2024-12-21 13:14:02,596 - aiogram.dispatcher - INFO - Polling stopped for bot @dofgd345borbot id=7101171025 - 'bobr123'
2024-12-21 13:14:02,596 - aiogram.dispatcher - INFO - Polling stopped
2024-12-21 13:14:12,737 - aiogram.dispatcher - INFO - Start polling
2024-12-21 13:14:12,775 - aiogram.dispatcher - INFO - Run polling for bot @dofgd345borbot id=7101171025 - 'bobr123'
2024-12-21 13:14:13,762 - aiogram.event - INFO - Update id=166847778 is not handled. Duration 8 ms by bot id=7101171025
2024-12-21 13:14:13,762 - aiogram.event - ERROR - Cause exception while process update id=166847778 by bot id=7101171025
AttributeError: 'dict' object has no attribute 'pk'
Traceback (most recent call last):
  File "/home/bybr/Desktop/english_bot/.venv/lib/python3.12/site-packages/aiogram/dispatcher/dispatcher.py", line 309, in _process_update
    response = await self.feed_update(bot, update, **kwargs)
               ^^^^^^^^^^^^^^^^^^^^^^^^^^^^^^^^^^^^^^^^^^^^^
  File "/home/bybr/Desktop/english_bot/.venv/lib/python3.12/site-packages/aiogram/dispatcher/dispatcher.py", line 158, in feed_update
    response = await self.update.wrap_outer_middleware(
               ^^^^^^^^^^^^^^^^^^^^^^^^^^^^^^^^^^^^^^^^
  File "/home/bybr/Desktop/english_bot/.venv/lib/python3.12/site-packages/aiogram/dispatcher/middlewares/error.py", line 25, in __call__
    return await handler(event, data)
           ^^^^^^^^^^^^^^^^^^^^^^^^^^
  File "/home/bybr/Desktop/english_bot/.venv/lib/python3.12/site-packages/aiogram/dispatcher/middlewares/user_context.py", line 56, in __call__
    return await handler(event, data)
           ^^^^^^^^^^^^^^^^^^^^^^^^^^
  File "/home/bybr/Desktop/english_bot/.venv/lib/python3.12/site-packages/aiogram/fsm/middleware.py", line 42, in __call__
    return await handler(event, data)
           ^^^^^^^^^^^^^^^^^^^^^^^^^^
  File "/home/bybr/Desktop/english_bot/.venv/lib/python3.12/site-packages/aiogram/dispatcher/event/telegram.py", line 121, in trigger
    return await wrapped_inner(event, kwargs)
           ^^^^^^^^^^^^^^^^^^^^^^^^^^^^^^^^^^
  File "/home/bybr/Desktop/english_bot/.venv/lib/python3.12/site-packages/aiogram/dispatcher/event/handler.py", line 43, in call
    return await wrapped()
           ^^^^^^^^^^^^^^^
  File "/home/bybr/Desktop/english_bot/.venv/lib/python3.12/site-packages/aiogram/dispatcher/dispatcher.py", line 276, in _listen_update
    return await self.propagate_event(update_type=update_type, event=event, **kwargs)
           ^^^^^^^^^^^^^^^^^^^^^^^^^^^^^^^^^^^^^^^^^^^^^^^^^^^^^^^^^^^^^^^^^^^^^^^^^^
  File "/home/bybr/Desktop/english_bot/.venv/lib/python3.12/site-packages/aiogram/dispatcher/router.py", line 146, in propagate_event
    return await observer.wrap_outer_middleware(_wrapped, event=event, data=kwargs)
           ^^^^^^^^^^^^^^^^^^^^^^^^^^^^^^^^^^^^^^^^^^^^^^^^^^^^^^^^^^^^^^^^^^^^^^^^
  File "/home/bybr/Desktop/english_bot/.venv/lib/python3.12/site-packages/aiogram/dispatcher/router.py", line 141, in _wrapped
    return await self._propagate_event(
           ^^^^^^^^^^^^^^^^^^^^^^^^^^^^
  File "/home/bybr/Desktop/english_bot/.venv/lib/python3.12/site-packages/aiogram/dispatcher/router.py", line 174, in _propagate_event
    response = await router.propagate_event(update_type=update_type, event=event, **kwargs)
               ^^^^^^^^^^^^^^^^^^^^^^^^^^^^^^^^^^^^^^^^^^^^^^^^^^^^^^^^^^^^^^^^^^^^^^^^^^^^
  File "/home/bybr/Desktop/english_bot/.venv/lib/python3.12/site-packages/aiogram/dispatcher/router.py", line 146, in propagate_event
    return await observer.wrap_outer_middleware(_wrapped, event=event, data=kwargs)
           ^^^^^^^^^^^^^^^^^^^^^^^^^^^^^^^^^^^^^^^^^^^^^^^^^^^^^^^^^^^^^^^^^^^^^^^^
  File "/home/bybr/Desktop/english_bot/.venv/lib/python3.12/site-packages/aiogram/dispatcher/router.py", line 141, in _wrapped
    return await self._propagate_event(
           ^^^^^^^^^^^^^^^^^^^^^^^^^^^^
  File "/home/bybr/Desktop/english_bot/.venv/lib/python3.12/site-packages/aiogram/dispatcher/router.py", line 166, in _propagate_event
    response = await observer.trigger(event, **kwargs)
               ^^^^^^^^^^^^^^^^^^^^^^^^^^^^^^^^^^^^^^^
  File "/home/bybr/Desktop/english_bot/.venv/lib/python3.12/site-packages/aiogram/dispatcher/event/telegram.py", line 121, in trigger
    return await wrapped_inner(event, kwargs)
           ^^^^^^^^^^^^^^^^^^^^^^^^^^^^^^^^^^
  File "/home/bybr/Desktop/english_bot/telegram_bot/core/middlewares.py", line 23, in __call__
    return await handler(event, data)
           ^^^^^^^^^^^^^^^^^^^^^^^^^^
  File "/home/bybr/Desktop/english_bot/.venv/lib/python3.12/site-packages/aiogram/dispatcher/event/handler.py", line 43, in call
    return await wrapped()
           ^^^^^^^^^^^^^^^
  File "/home/bybr/Desktop/english_bot/telegram_bot/core/handlers.py", line 44, in handle_text_message
    socket_result = await send_to_websocket(obj_chat.pk, obj_message.pk, message.text)
                                                         ^^^^^^^^^^^^^^
AttributeError: 'dict' object has no attribute 'pk'
2024-12-21 13:15:19,713 - aiogram.dispatcher - WARNING - Received SIGINT signal
2024-12-21 13:15:19,714 - aiogram.dispatcher - INFO - Polling stopped for bot @dofgd345borbot id=7101171025 - 'bobr123'
2024-12-21 13:15:19,714 - aiogram.dispatcher - INFO - Polling stopped
2024-12-21 13:15:22,512 - aiogram.dispatcher - INFO - Start polling
2024-12-21 13:15:22,563 - aiogram.dispatcher - INFO - Run polling for bot @dofgd345borbot id=7101171025 - 'bobr123'
2024-12-21 13:15:23,361 - telegram_bot.core.websocket_request - INFO - Message sent to websocket: 1 / 1 / 456
2024-12-21 13:15:23,491 - aiogram.event - INFO - Update id=166847779 is handled. Duration 146 ms by bot id=7101171025
2024-12-21 13:15:27,639 - telegram_bot.core.websocket_request - INFO - Message sent to websocket: 1 / 1 / 345
2024-12-21 13:15:27,692 - aiogram.event - INFO - Update id=166847780 is handled. Duration 60 ms by bot id=7101171025
2024-12-21 13:15:31,430 - telegram_bot.core.websocket_request - INFO - Message sent to websocket: 1 / 1 / хеллоу
2024-12-21 13:15:31,485 - aiogram.event - INFO - Update id=166847781 is handled. Duration 65 ms by bot id=7101171025
2024-12-21 13:17:25,113 - aiogram.dispatcher - WARNING - Received SIGINT signal
2024-12-21 13:17:25,113 - aiogram.dispatcher - INFO - Polling stopped for bot @dofgd345borbot id=7101171025 - 'bobr123'
2024-12-21 13:17:25,113 - aiogram.dispatcher - INFO - Polling stopped
2024-12-21 13:17:27,979 - aiogram.dispatcher - INFO - Start polling
2024-12-21 13:17:28,018 - aiogram.dispatcher - INFO - Run polling for bot @dofgd345borbot id=7101171025 - 'bobr123'
2024-12-21 13:17:29,906 - telegram_bot.core.db_request - ERROR - Create message: 'dict' object has no attribute 'append'
2024-12-21 13:17:30,139 - aiogram.event - INFO - Update id=166847782 is handled. Duration 239 ms by bot id=7101171025
2024-12-21 13:18:31,108 - telegram_bot.core.db_request - ERROR - Create system action: database is locked
2024-12-21 13:18:31,109 - telegram_bot.core.db_request - ERROR - Create message: 'dict' object has no attribute 'append'
2024-12-21 13:18:31,238 - aiogram.event - INFO - Update id=166847783 is handled. Duration 5141 ms by bot id=7101171025
2024-12-21 13:18:35,023 - aiogram.dispatcher - WARNING - Received SIGINT signal
2024-12-21 13:18:35,024 - aiogram.dispatcher - INFO - Polling stopped for bot @dofgd345borbot id=7101171025 - 'bobr123'
2024-12-21 13:18:35,024 - aiogram.dispatcher - INFO - Polling stopped
2024-12-21 13:18:38,311 - aiogram.dispatcher - INFO - Start polling
2024-12-21 13:18:38,357 - aiogram.dispatcher - INFO - Run polling for bot @dofgd345borbot id=7101171025 - 'bobr123'
2024-12-21 13:19:03,648 - telegram_bot.core.db_request - ERROR - Create system action: database is locked
2024-12-21 13:19:03,649 - telegram_bot.core.db_request - ERROR - Create message: 'dict' object has no attribute 'append'
2024-12-21 13:19:03,785 - aiogram.event - INFO - Update id=166847784 is handled. Duration 5157 ms by bot id=7101171025
2024-12-21 13:19:20,470 - aiogram.dispatcher - WARNING - Received SIGINT signal
2024-12-21 13:19:20,471 - aiogram.dispatcher - INFO - Polling stopped for bot @dofgd345borbot id=7101171025 - 'bobr123'
2024-12-21 13:19:20,471 - aiogram.dispatcher - INFO - Polling stopped
2024-12-21 13:21:44,813 - aiogram.dispatcher - INFO - Start polling
2024-12-21 13:21:44,853 - aiogram.dispatcher - INFO - Run polling for bot @dofgd345borbot id=7101171025 - 'bobr123'
2024-12-21 13:21:51,465 - telegram_bot.core.db_request - ERROR - Create system action: database is locked
2024-12-21 13:21:51,467 - telegram_bot.core.db_request - ERROR - Create message: 'dict' object has no attribute 'append'
2024-12-21 13:21:51,604 - aiogram.event - INFO - Update id=166847785 is handled. Duration 5154 ms by bot id=7101171025
2024-12-21 13:23:24,634 - aiogram.dispatcher - WARNING - Received SIGINT signal
2024-12-21 13:23:24,635 - aiogram.dispatcher - INFO - Polling stopped for bot @dofgd345borbot id=7101171025 - 'bobr123'
2024-12-21 13:23:24,635 - aiogram.dispatcher - INFO - Polling stopped
2024-12-21 13:24:09,346 - aiogram.dispatcher - INFO - Start polling
2024-12-21 13:24:09,385 - aiogram.dispatcher - INFO - Run polling for bot @dofgd345borbot id=7101171025 - 'bobr123'
2024-12-21 13:24:11,875 - telegram_bot.core.websocket_request - INFO - Message sent to websocket: 2 / 1 / 345
2024-12-21 13:24:11,950 - aiogram.event - INFO - Update id=166847786 is handled. Duration 273 ms by bot id=7101171025
2024-12-21 13:24:13,666 - telegram_bot.core.websocket_request - INFO - Message sent to websocket: 2 / 1 / 34
2024-12-21 13:24:13,727 - aiogram.event - INFO - Update id=166847787 is handled. Duration 68 ms by bot id=7101171025
2024-12-21 13:24:14,635 - telegram_bot.core.websocket_request - INFO - Message sent to websocket: 2 / 1 / 346
2024-12-21 13:24:14,711 - aiogram.event - INFO - Update id=166847788 is handled. Duration 83 ms by bot id=7101171025
2024-12-21 13:24:15,510 - telegram_bot.core.websocket_request - INFO - Message sent to websocket: 2 / 1 / 436
2024-12-21 13:24:15,579 - aiogram.event - INFO - Update id=166847789 is handled. Duration 76 ms by bot id=7101171025
2024-12-21 13:24:16,183 - telegram_bot.core.websocket_request - INFO - Message sent to websocket: 2 / 1 / 1243
2024-12-21 13:24:16,241 - aiogram.event - INFO - Update id=166847790 is handled. Duration 66 ms by bot id=7101171025
2024-12-21 13:26:57,767 - aiogram.dispatcher - WARNING - Received SIGINT signal
2024-12-21 13:26:57,768 - aiogram.dispatcher - INFO - Polling stopped for bot @dofgd345borbot id=7101171025 - 'bobr123'
2024-12-21 13:26:57,768 - aiogram.dispatcher - INFO - Polling stopped
2024-12-21 13:27:03,376 - aiogram.dispatcher - INFO - Start polling
2024-12-21 13:27:03,415 - aiogram.dispatcher - INFO - Run polling for bot @dofgd345borbot id=7101171025 - 'bobr123'
2024-12-21 13:27:06,483 - telegram_bot.core.websocket_request - INFO - Message sent to websocket: 2 / 1 / hello
2024-12-21 13:27:06,612 - aiogram.event - INFO - Update id=166847791 is handled. Duration 142 ms by bot id=7101171025
2024-12-21 13:27:08,322 - telegram_bot.core.websocket_request - INFO - Message sent to websocket: 2 / 1 / 34534
2024-12-21 13:27:08,376 - aiogram.event - INFO - Update id=166847792 is handled. Duration 61 ms by bot id=7101171025
2024-12-21 13:33:08,825 - aiogram.dispatcher - INFO - Start polling
2024-12-21 13:33:08,858 - aiogram.dispatcher - INFO - Run polling for bot @dofgd345borbot id=7101171025 - 'bobr123'
2024-12-21 16:45:23,581 - aiogram.dispatcher - INFO - Start polling
2024-12-21 16:45:23,621 - aiogram.dispatcher - INFO - Run polling for bot @dofgd345borbot id=7101171025 - 'bobr123'
2024-12-21 16:47:39,739 - telegram_bot.core.websocket_request - INFO - Message sent to websocket: 2 / 1 / 123
2024-12-21 16:47:39,884 - aiogram.event - INFO - Update id=166847793 is handled. Duration 157 ms by bot id=7101171025
2024-12-21 16:47:41,996 - telegram_bot.core.websocket_request - INFO - Message sent to websocket: 2 / 1 / 123
2024-12-21 16:47:42,067 - aiogram.event - INFO - Update id=166847794 is handled. Duration 80 ms by bot id=7101171025
2024-12-21 16:53:06,012 - aiogram.dispatcher - WARNING - Received SIGINT signal
2024-12-21 16:53:06,013 - aiogram.dispatcher - INFO - Polling stopped for bot @dofgd345borbot id=7101171025 - 'bobr123'
2024-12-21 16:53:06,013 - aiogram.dispatcher - INFO - Polling stopped
2024-12-21 16:54:18,358 - aiogram.dispatcher - INFO - Start polling
2024-12-21 16:54:18,401 - aiogram.dispatcher - INFO - Run polling for bot @dofgd345borbot id=7101171025 - 'bobr123'
2024-12-21 17:39:03,238 - aiogram.dispatcher - INFO - Start polling
2024-12-21 17:39:03,283 - aiogram.dispatcher - INFO - Run polling for bot @dofgd345borbot id=7101171025 - 'bobr123'
2024-12-21 17:39:13,993 - telegram_bot.core.websocket_request - INFO - Message sent to websocket: 2 / 1 / test
2024-12-21 17:39:14,131 - aiogram.event - INFO - Update id=166847798 is handled. Duration 149 ms by bot id=7101171025
2024-12-21 17:39:17,142 - telegram_bot.core.websocket_request - INFO - Message sent to websocket: 2 / 1 / test
2024-12-21 17:39:17,195 - aiogram.event - INFO - Update id=166847799 is handled. Duration 61 ms by bot id=7101171025
2024-12-21 17:40:11,440 - aiogram.dispatcher - WARNING - Received SIGINT signal
2024-12-21 17:40:11,440 - aiogram.dispatcher - INFO - Polling stopped for bot @dofgd345borbot id=7101171025 - 'bobr123'
2024-12-21 17:40:11,441 - aiogram.dispatcher - INFO - Polling stopped
2024-12-21 17:40:14,266 - aiogram.dispatcher - INFO - Start polling
2024-12-21 17:40:14,301 - aiogram.dispatcher - INFO - Run polling for bot @dofgd345borbot id=7101171025 - 'bobr123'
2024-12-21 17:40:29,443 - telegram_bot.core.websocket_request - INFO - Message sent to websocket: 2 / 1 / test
2024-12-21 17:40:29,597 - aiogram.event - INFO - Update id=166847800 is handled. Duration 164 ms by bot id=7101171025
2024-12-21 17:40:36,713 - telegram_bot.core.websocket_request - INFO - Message sent to websocket: 2 / 1 / hello
2024-12-21 17:40:36,803 - aiogram.event - INFO - Update id=166847801 is handled. Duration 98 ms by bot id=7101171025
2024-12-21 17:41:04,269 - telegram_bot.core.websocket_request - INFO - Message sent to websocket: 2 / 1 / 345
2024-12-21 17:41:04,483 - aiogram.event - INFO - Update id=166847802 is handled. Duration 222 ms by bot id=7101171025
2024-12-21 17:41:21,837 - telegram_bot.core.websocket_request - INFO - Message sent to websocket: 2 / 1 / тест повідомлення
2024-12-21 17:41:22,231 - aiogram.event - INFO - Update id=166847803 is handled. Duration 401 ms by bot id=7101171025
2024-12-21 17:52:59,093 - aiogram.dispatcher - WARNING - Received SIGINT signal
2024-12-21 17:52:59,094 - aiogram.dispatcher - INFO - Polling stopped for bot @dofgd345borbot id=7101171025 - 'bobr123'
2024-12-21 17:52:59,094 - aiogram.dispatcher - INFO - Polling stopped
2024-12-21 17:53:01,951 - aiogram.dispatcher - INFO - Start polling
2024-12-21 17:53:01,989 - aiogram.dispatcher - INFO - Run polling for bot @dofgd345borbot id=7101171025 - 'bobr123'
2024-12-21 17:53:05,357 - telegram_bot.core.websocket_request - ERROR - ##################################################
2024-12-21 17:53:05,357 - telegram_bot.core.websocket_request - ERROR - Send to websocket: Cannot connect to host 127.0.0.1:8000 ssl:default [Connect call failed ('127.0.0.1', 8000)]
2024-12-21 17:53:05,359 - telegram_bot.core.websocket_request - ERROR - Traceback (most recent call last):
  File "/home/bybr/Desktop/english_bot/.venv/lib/python3.12/site-packages/aiohttp/connector.py", line 1109, in _wrap_create_connection
    sock = await aiohappyeyeballs.start_connection(
           ^^^^^^^^^^^^^^^^^^^^^^^^^^^^^^^^^^^^^^^^
  File "/home/bybr/Desktop/english_bot/.venv/lib/python3.12/site-packages/aiohappyeyeballs/impl.py", line 104, in start_connection
    raise first_exception
  File "/home/bybr/Desktop/english_bot/.venv/lib/python3.12/site-packages/aiohappyeyeballs/impl.py", line 82, in start_connection
    sock = await _connect_sock(
           ^^^^^^^^^^^^^^^^^^^^
  File "/home/bybr/Desktop/english_bot/.venv/lib/python3.12/site-packages/aiohappyeyeballs/impl.py", line 174, in _connect_sock
    await loop.sock_connect(sock, address)
  File "/usr/lib/python3.12/asyncio/selector_events.py", line 651, in sock_connect
    return await fut
           ^^^^^^^^^
  File "/usr/lib/python3.12/asyncio/selector_events.py", line 691, in _sock_connect_cb
    raise OSError(err, f'Connect call failed {address}')
ConnectionRefusedError: [Errno 111] Connect call failed ('127.0.0.1', 8000)

The above exception was the direct cause of the following exception:

Traceback (most recent call last):
  File "/home/bybr/Desktop/english_bot/telegram_bot/core/websocket_request.py", line 17, in send_to_websocket
    async with session.ws_connect(f"ws://{domain}/ws/chat/{chat_id}/") as ws:
  File "/home/bybr/Desktop/english_bot/.venv/lib/python3.12/site-packages/aiohttp/client.py", line 1360, in __aenter__
    self._resp: _RetType = await self._coro
                           ^^^^^^^^^^^^^^^^
  File "/home/bybr/Desktop/english_bot/.venv/lib/python3.12/site-packages/aiohttp/client.py", line 938, in _ws_connect
    resp = await self.request(
           ^^^^^^^^^^^^^^^^^^^
  File "/home/bybr/Desktop/english_bot/.venv/lib/python3.12/site-packages/aiohttp/client.py", line 663, in _request
    conn = await self._connector.connect(
           ^^^^^^^^^^^^^^^^^^^^^^^^^^^^^^
  File "/home/bybr/Desktop/english_bot/.venv/lib/python3.12/site-packages/aiohttp/connector.py", line 538, in connect
    proto = await self._create_connection(req, traces, timeout)
            ^^^^^^^^^^^^^^^^^^^^^^^^^^^^^^^^^^^^^^^^^^^^^^^^^^^
  File "/home/bybr/Desktop/english_bot/.venv/lib/python3.12/site-packages/aiohttp/connector.py", line 1050, in _create_connection
    _, proto = await self._create_direct_connection(req, traces, timeout)
               ^^^^^^^^^^^^^^^^^^^^^^^^^^^^^^^^^^^^^^^^^^^^^^^^^^^^^^^^^^
  File "/home/bybr/Desktop/english_bot/.venv/lib/python3.12/site-packages/aiohttp/connector.py", line 1384, in _create_direct_connection
    raise last_exc
  File "/home/bybr/Desktop/english_bot/.venv/lib/python3.12/site-packages/aiohttp/connector.py", line 1353, in _create_direct_connection
    transp, proto = await self._wrap_create_connection(
                    ^^^^^^^^^^^^^^^^^^^^^^^^^^^^^^^^^^^
  File "/home/bybr/Desktop/english_bot/.venv/lib/python3.12/site-packages/aiohttp/connector.py", line 1124, in _wrap_create_connection
    raise client_error(req.connection_key, exc) from exc
aiohttp.client_exceptions.ClientConnectorError: Cannot connect to host 127.0.0.1:8000 ssl:default [Connect call failed ('127.0.0.1', 8000)]

2024-12-21 17:53:05,359 - telegram_bot.core.websocket_request - ERROR - ##################################################
2024-12-21 17:53:05,605 - aiogram.event - INFO - Update id=166847804 is handled. Duration 256 ms by bot id=7101171025
2024-12-21 18:08:45,176 - telegram_bot.core.websocket_request - INFO - Message sent to websocket: 2 / 1 / sdfsf
2024-12-21 18:08:45,326 - aiogram.event - INFO - Update id=166847805 is handled. Duration 160 ms by bot id=7101171025
2024-12-21 18:08:56,833 - telegram_bot.core.websocket_request - INFO - Message sent to websocket: 2 / 1 / 3466
2024-12-21 18:08:57,073 - aiogram.event - INFO - Update id=166847806 is handled. Duration 248 ms by bot id=7101171025
2024-12-21 18:41:56,883 - telegram_bot.core.websocket_request - INFO - Message sent to websocket: 2 / 1 / 12335
2024-12-21 18:41:57,020 - aiogram.event - INFO - Update id=166847807 is handled. Duration 144 ms by bot id=7101171025
2024-12-21 19:00:28,489 - telegram_bot.core.websocket_request - INFO - Message sent to websocket: 2 / 1 / test
2024-12-21 19:00:28,654 - aiogram.event - INFO - Update id=166847808 is handled. Duration 176 ms by bot id=7101171025
2024-12-21 19:00:35,543 - aiogram.dispatcher - WARNING - Received SIGINT signal
2024-12-21 19:00:35,543 - aiogram.dispatcher - INFO - Polling stopped for bot @dofgd345borbot id=7101171025 - 'bobr123'
2024-12-21 19:00:35,543 - aiogram.dispatcher - INFO - Polling stopped
2024-12-21 19:00:38,331 - aiogram.dispatcher - INFO - Start polling
2024-12-21 19:00:38,375 - aiogram.dispatcher - INFO - Run polling for bot @dofgd345borbot id=7101171025 - 'bobr123'
2024-12-21 19:00:39,722 - telegram_bot.core.websocket_request - INFO - Message sent to websocket: 2 / 1 / 235
2024-12-21 19:00:39,868 - aiogram.event - INFO - Update id=166847809 is handled. Duration 157 ms by bot id=7101171025
2024-12-21 19:00:44,082 - telegram_bot.core.websocket_request - INFO - Message sent to websocket: 2 / 1 / 214
2024-12-21 19:00:44,167 - aiogram.event - INFO - Update id=166847810 is handled. Duration 94 ms by bot id=7101171025
2024-12-21 19:00:49,400 - telegram_bot.core.websocket_request - INFO - Message sent to websocket: 2 / 1 / 234
2024-12-21 19:00:49,511 - aiogram.event - INFO - Update id=166847811 is handled. Duration 121 ms by bot id=7101171025
2024-12-22 06:46:14,962 - aiogram.dispatcher - INFO - Start polling
2024-12-22 06:46:15,009 - aiogram.dispatcher - INFO - Run polling for bot @dofgd345borbot id=7101171025 - 'bobr123'
2024-12-22 06:55:00,722 - aiogram.dispatcher - WARNING - Received SIGINT signal
2024-12-22 06:55:00,722 - aiogram.dispatcher - INFO - Polling stopped for bot @dofgd345borbot id=7101171025 - 'bobr123'
2024-12-22 06:55:00,722 - aiogram.dispatcher - INFO - Polling stopped
2024-12-22 06:58:14,052 - aiogram.dispatcher - INFO - Start polling
2024-12-22 06:58:14,101 - aiogram.dispatcher - INFO - Run polling for bot @dofgd345borbot id=7101171025 - 'bobr123'
2024-12-22 06:58:21,397 - telegram_bot.core.websocket_request - INFO - Message sent to websocket: 2 / 1 / hello
2024-12-22 06:58:21,596 - aiogram.event - INFO - Update id=166847812 is handled. Duration 210 ms by bot id=7101171025
2024-12-22 09:11:27,911 - aiogram.dispatcher - INFO - Start polling
2024-12-22 09:11:27,946 - aiogram.dispatcher - INFO - Run polling for bot @dofgd345borbot id=7101171025 - 'bobr123'
2024-12-22 09:11:33,538 - telegram_bot.core.websocket_request - INFO - Message sent to websocket: 2 / 1 / teest
2024-12-22 09:11:33,721 - aiogram.event - INFO - Update id=166847813 is handled. Duration 197 ms by bot id=7101171025
2024-12-22 09:12:10,873 - telegram_bot.core.websocket_request - INFO - Message sent to websocket: 2 / 1 / 123
2024-12-22 09:12:11,145 - aiogram.event - INFO - Update id=166847814 is handled. Duration 280 ms by bot id=7101171025
2024-12-22 09:14:28,831 - aiogram.dispatcher - WARNING - Received SIGINT signal
2024-12-22 09:14:28,831 - aiogram.dispatcher - INFO - Polling stopped for bot @dofgd345borbot id=7101171025 - 'bobr123'
2024-12-22 09:14:28,831 - aiogram.dispatcher - INFO - Polling stopped
2024-12-22 09:14:31,686 - aiogram.dispatcher - INFO - Start polling
2024-12-22 09:14:31,720 - aiogram.dispatcher - INFO - Run polling for bot @dofgd345borbot id=7101171025 - 'bobr123'
2024-12-22 09:14:35,418 - telegram_bot.core.websocket_request - INFO - Message sent to websocket: 2 / 1 / тест запит
2024-12-22 09:14:35,653 - aiogram.event - INFO - Update id=166847815 is handled. Duration 247 ms by bot id=7101171025
2024-12-22 09:15:39,925 - aiogram.dispatcher - WARNING - Received SIGINT signal
2024-12-22 09:15:39,925 - aiogram.dispatcher - INFO - Polling stopped for bot @dofgd345borbot id=7101171025 - 'bobr123'
2024-12-22 09:15:39,925 - aiogram.dispatcher - INFO - Polling stopped
2024-12-22 09:15:42,869 - aiogram.dispatcher - INFO - Start polling
2024-12-22 09:15:42,912 - aiogram.dispatcher - INFO - Run polling for bot @dofgd345borbot id=7101171025 - 'bobr123'
2024-12-22 09:15:45,029 - telegram_bot.core.websocket_request - INFO - Message sent to websocket: 2 / 1 / 234
2024-12-22 09:15:45,283 - aiogram.event - INFO - Update id=166847816 is handled. Duration 263 ms by bot id=7101171025
2024-12-22 09:18:14,060 - telegram_bot.core.websocket_request - INFO - Message sent to websocket: 2 / 1 / 234
2024-12-22 09:18:14,240 - aiogram.event - INFO - Update id=166847817 is handled. Duration 190 ms by bot id=7101171025
2024-12-22 10:02:28,095 - telegram_bot.core.websocket_request - INFO - Message sent to websocket: 2 / 1 / 235
2024-12-22 10:02:28,331 - aiogram.event - INFO - Update id=166847818 is handled. Duration 242 ms by bot id=7101171025
2024-12-22 10:04:37,960 - telegram_bot.core.websocket_request - INFO - Message sent to websocket: 2 / 1 / 3456
2024-12-22 10:04:38,138 - aiogram.event - INFO - Update id=166847819 is handled. Duration 184 ms by bot id=7101171025
2024-12-22 10:05:07,743 - telegram_bot.core.websocket_request - INFO - Message sent to websocket: 2 / 1 / 346
2024-12-22 10:05:07,941 - aiogram.event - INFO - Update id=166847820 is handled. Duration 205 ms by bot id=7101171025
2024-12-22 12:01:40,117 - aiogram.dispatcher - INFO - Start polling
2024-12-22 12:01:40,160 - aiogram.dispatcher - INFO - Run polling for bot @dofgd345borbot id=7101171025 - 'bobr123'
2024-12-22 12:02:28,825 - telegram_bot.core.websocket_request - INFO - Message sent to websocket: 2 / 1 / 346346
2024-12-22 12:02:29,008 - aiogram.event - INFO - Update id=166847822 is handled. Duration 192 ms by bot id=7101171025
2024-12-22 14:31:29,548 - aiogram.dispatcher - INFO - Start polling
2024-12-22 14:31:29,587 - aiogram.dispatcher - INFO - Run polling for bot @dofgd345borbot id=7101171025 - 'bobr123'
2024-12-22 14:31:31,769 - telegram_bot.core.websocket_request - INFO - Message sent to websocket: 2 / 1 / 235
2024-12-22 14:31:32,060 - aiogram.event - INFO - Update id=166847824 is handled. Duration 301 ms by bot id=7101171025
2024-12-22 14:40:54,620 - telegram_bot.core.websocket_request - INFO - Message sent to websocket: 2 / 1 / 214
2024-12-22 14:40:54,791 - aiogram.event - INFO - Update id=166847825 is handled. Duration 178 ms by bot id=7101171025
2024-12-22 14:49:10,791 - telegram_bot.core.websocket_request - INFO - Message sent to websocket: 2 / 1 / 23
2024-12-22 14:49:10,938 - aiogram.event - INFO - Update id=166847826 is handled. Duration 159 ms by bot id=7101171025
2024-12-22 14:53:00,947 - telegram_bot.core.websocket_request - INFO - Message sent to websocket: 2 / 1 / 2354
2024-12-22 14:53:01,106 - aiogram.event - INFO - Update id=166847827 is handled. Duration 171 ms by bot id=7101171025
2024-12-22 14:53:05,983 - telegram_bot.core.websocket_request - INFO - Message sent to websocket: 2 / 1 / 124
2024-12-22 14:53:06,057 - aiogram.event - INFO - Update id=166847828 is handled. Duration 81 ms by bot id=7101171025
2024-12-22 14:53:13,667 - telegram_bot.core.websocket_request - INFO - Message sent to websocket: 2 / 1 / 124
2024-12-22 14:53:13,831 - aiogram.event - INFO - Update id=166847829 is handled. Duration 171 ms by bot id=7101171025
2024-12-22 14:53:28,566 - telegram_bot.core.websocket_request - INFO - Message sent to websocket: 2 / 1 / 234
2024-12-22 14:53:28,646 - aiogram.event - INFO - Update id=166847830 is handled. Duration 85 ms by bot id=7101171025
2024-12-22 14:54:42,374 - telegram_bot.core.websocket_request - ERROR - ##################################################
2024-12-22 14:54:42,374 - telegram_bot.core.websocket_request - ERROR - Send to websocket: Cannot connect to host 127.0.0.1:8000 ssl:default [Connect call failed ('127.0.0.1', 8000)]
2024-12-22 14:54:42,377 - telegram_bot.core.websocket_request - ERROR - Traceback (most recent call last):
  File "/home/bybr/Desktop/english_bot/.venv/lib/python3.12/site-packages/aiohttp/connector.py", line 1109, in _wrap_create_connection
    sock = await aiohappyeyeballs.start_connection(
           ^^^^^^^^^^^^^^^^^^^^^^^^^^^^^^^^^^^^^^^^
  File "/home/bybr/Desktop/english_bot/.venv/lib/python3.12/site-packages/aiohappyeyeballs/impl.py", line 104, in start_connection
    raise first_exception
  File "/home/bybr/Desktop/english_bot/.venv/lib/python3.12/site-packages/aiohappyeyeballs/impl.py", line 82, in start_connection
    sock = await _connect_sock(
           ^^^^^^^^^^^^^^^^^^^^
  File "/home/bybr/Desktop/english_bot/.venv/lib/python3.12/site-packages/aiohappyeyeballs/impl.py", line 174, in _connect_sock
    await loop.sock_connect(sock, address)
  File "/usr/lib/python3.12/asyncio/selector_events.py", line 651, in sock_connect
    return await fut
           ^^^^^^^^^
  File "/usr/lib/python3.12/asyncio/selector_events.py", line 691, in _sock_connect_cb
    raise OSError(err, f'Connect call failed {address}')
ConnectionRefusedError: [Errno 111] Connect call failed ('127.0.0.1', 8000)

The above exception was the direct cause of the following exception:

Traceback (most recent call last):
  File "/home/bybr/Desktop/english_bot/telegram_bot/core/websocket_request.py", line 17, in send_to_websocket
    async with session.ws_connect(f"ws://{domain}/ws/chat/{chat_id}/") as ws:
  File "/home/bybr/Desktop/english_bot/.venv/lib/python3.12/site-packages/aiohttp/client.py", line 1360, in __aenter__
    self._resp: _RetType = await self._coro
                           ^^^^^^^^^^^^^^^^
  File "/home/bybr/Desktop/english_bot/.venv/lib/python3.12/site-packages/aiohttp/client.py", line 938, in _ws_connect
    resp = await self.request(
           ^^^^^^^^^^^^^^^^^^^
  File "/home/bybr/Desktop/english_bot/.venv/lib/python3.12/site-packages/aiohttp/client.py", line 663, in _request
    conn = await self._connector.connect(
           ^^^^^^^^^^^^^^^^^^^^^^^^^^^^^^
  File "/home/bybr/Desktop/english_bot/.venv/lib/python3.12/site-packages/aiohttp/connector.py", line 538, in connect
    proto = await self._create_connection(req, traces, timeout)
            ^^^^^^^^^^^^^^^^^^^^^^^^^^^^^^^^^^^^^^^^^^^^^^^^^^^
  File "/home/bybr/Desktop/english_bot/.venv/lib/python3.12/site-packages/aiohttp/connector.py", line 1050, in _create_connection
    _, proto = await self._create_direct_connection(req, traces, timeout)
               ^^^^^^^^^^^^^^^^^^^^^^^^^^^^^^^^^^^^^^^^^^^^^^^^^^^^^^^^^^
  File "/home/bybr/Desktop/english_bot/.venv/lib/python3.12/site-packages/aiohttp/connector.py", line 1384, in _create_direct_connection
    raise last_exc
  File "/home/bybr/Desktop/english_bot/.venv/lib/python3.12/site-packages/aiohttp/connector.py", line 1353, in _create_direct_connection
    transp, proto = await self._wrap_create_connection(
                    ^^^^^^^^^^^^^^^^^^^^^^^^^^^^^^^^^^^
  File "/home/bybr/Desktop/english_bot/.venv/lib/python3.12/site-packages/aiohttp/connector.py", line 1124, in _wrap_create_connection
    raise client_error(req.connection_key, exc) from exc
aiohttp.client_exceptions.ClientConnectorError: Cannot connect to host 127.0.0.1:8000 ssl:default [Connect call failed ('127.0.0.1', 8000)]

2024-12-22 14:54:42,377 - telegram_bot.core.websocket_request - ERROR - ##################################################
2024-12-22 14:54:42,739 - aiogram.event - INFO - Update id=166847831 is handled. Duration 368 ms by bot id=7101171025
2024-12-22 14:54:45,308 - telegram_bot.core.websocket_request - INFO - Message sent to websocket: 2 / 1 / 234
2024-12-22 14:54:45,398 - aiogram.event - INFO - Update id=166847832 is handled. Duration 101 ms by bot id=7101171025
2024-12-22 14:55:41,324 - telegram_bot.core.websocket_request - INFO - Message sent to websocket: 2 / 1 / 2354
2024-12-22 14:55:41,490 - aiogram.event - INFO - Update id=166847833 is handled. Duration 175 ms by bot id=7101171025
2024-12-22 14:56:02,529 - telegram_bot.core.websocket_request - INFO - Message sent to websocket: 2 / 1 / 235
2024-12-22 14:56:02,699 - aiogram.event - INFO - Update id=166847834 is handled. Duration 181 ms by bot id=7101171025
2024-12-22 14:56:10,944 - telegram_bot.core.websocket_request - ERROR - ##################################################
2024-12-22 14:56:10,944 - telegram_bot.core.websocket_request - ERROR - Send to websocket: Cannot connect to host 127.0.0.1:8000 ssl:default [Connect call failed ('127.0.0.1', 8000)]
2024-12-22 14:56:10,945 - telegram_bot.core.websocket_request - ERROR - Traceback (most recent call last):
  File "/home/bybr/Desktop/english_bot/.venv/lib/python3.12/site-packages/aiohttp/connector.py", line 1109, in _wrap_create_connection
    sock = await aiohappyeyeballs.start_connection(
           ^^^^^^^^^^^^^^^^^^^^^^^^^^^^^^^^^^^^^^^^
  File "/home/bybr/Desktop/english_bot/.venv/lib/python3.12/site-packages/aiohappyeyeballs/impl.py", line 104, in start_connection
    raise first_exception
  File "/home/bybr/Desktop/english_bot/.venv/lib/python3.12/site-packages/aiohappyeyeballs/impl.py", line 82, in start_connection
    sock = await _connect_sock(
           ^^^^^^^^^^^^^^^^^^^^
  File "/home/bybr/Desktop/english_bot/.venv/lib/python3.12/site-packages/aiohappyeyeballs/impl.py", line 174, in _connect_sock
    await loop.sock_connect(sock, address)
  File "/usr/lib/python3.12/asyncio/selector_events.py", line 651, in sock_connect
    return await fut
           ^^^^^^^^^
  File "/usr/lib/python3.12/asyncio/selector_events.py", line 691, in _sock_connect_cb
    raise OSError(err, f'Connect call failed {address}')
ConnectionRefusedError: [Errno 111] Connect call failed ('127.0.0.1', 8000)

The above exception was the direct cause of the following exception:

Traceback (most recent call last):
  File "/home/bybr/Desktop/english_bot/telegram_bot/core/websocket_request.py", line 17, in send_to_websocket
    async with session.ws_connect(f"ws://{domain}/ws/chat/{chat_id}/") as ws:
  File "/home/bybr/Desktop/english_bot/.venv/lib/python3.12/site-packages/aiohttp/client.py", line 1360, in __aenter__
    self._resp: _RetType = await self._coro
                           ^^^^^^^^^^^^^^^^
  File "/home/bybr/Desktop/english_bot/.venv/lib/python3.12/site-packages/aiohttp/client.py", line 938, in _ws_connect
    resp = await self.request(
           ^^^^^^^^^^^^^^^^^^^
  File "/home/bybr/Desktop/english_bot/.venv/lib/python3.12/site-packages/aiohttp/client.py", line 663, in _request
    conn = await self._connector.connect(
           ^^^^^^^^^^^^^^^^^^^^^^^^^^^^^^
  File "/home/bybr/Desktop/english_bot/.venv/lib/python3.12/site-packages/aiohttp/connector.py", line 538, in connect
    proto = await self._create_connection(req, traces, timeout)
            ^^^^^^^^^^^^^^^^^^^^^^^^^^^^^^^^^^^^^^^^^^^^^^^^^^^
  File "/home/bybr/Desktop/english_bot/.venv/lib/python3.12/site-packages/aiohttp/connector.py", line 1050, in _create_connection
    _, proto = await self._create_direct_connection(req, traces, timeout)
               ^^^^^^^^^^^^^^^^^^^^^^^^^^^^^^^^^^^^^^^^^^^^^^^^^^^^^^^^^^
  File "/home/bybr/Desktop/english_bot/.venv/lib/python3.12/site-packages/aiohttp/connector.py", line 1384, in _create_direct_connection
    raise last_exc
  File "/home/bybr/Desktop/english_bot/.venv/lib/python3.12/site-packages/aiohttp/connector.py", line 1353, in _create_direct_connection
    transp, proto = await self._wrap_create_connection(
                    ^^^^^^^^^^^^^^^^^^^^^^^^^^^^^^^^^^^
  File "/home/bybr/Desktop/english_bot/.venv/lib/python3.12/site-packages/aiohttp/connector.py", line 1124, in _wrap_create_connection
    raise client_error(req.connection_key, exc) from exc
aiohttp.client_exceptions.ClientConnectorError: Cannot connect to host 127.0.0.1:8000 ssl:default [Connect call failed ('127.0.0.1', 8000)]

2024-12-22 14:56:10,945 - telegram_bot.core.websocket_request - ERROR - ##################################################
2024-12-22 14:56:11,000 - aiogram.event - INFO - Update id=166847835 is handled. Duration 60 ms by bot id=7101171025
2024-12-22 14:56:13,034 - telegram_bot.core.websocket_request - INFO - Message sent to websocket: 2 / 1 / 235
2024-12-22 14:56:13,096 - aiogram.event - INFO - Update id=166847836 is handled. Duration 72 ms by bot id=7101171025
2024-12-22 14:56:30,103 - telegram_bot.core.websocket_request - INFO - Message sent to websocket: 2 / 1 / 124
2024-12-22 14:56:30,267 - aiogram.event - INFO - Update id=166847837 is handled. Duration 170 ms by bot id=7101171025
2024-12-22 15:21:00,540 - telegram_bot.core.websocket_request - INFO - Message sent to websocket: 2 / 1 / 234
2024-12-22 15:21:00,718 - aiogram.event - INFO - Update id=166847838 is handled. Duration 183 ms by bot id=7101171025
2024-12-22 15:23:32,562 - telegram_bot.core.websocket_request - INFO - Message sent to websocket: 2 / 1 / 235
2024-12-22 15:23:32,785 - aiogram.event - INFO - Update id=166847839 is handled. Duration 228 ms by bot id=7101171025
2024-12-22 15:23:39,314 - telegram_bot.core.websocket_request - INFO - Message sent to websocket: 2 / 1 / 2346
2024-12-22 15:23:39,407 - aiogram.event - INFO - Update id=166847840 is handled. Duration 99 ms by bot id=7101171025
2024-12-22 15:28:44,844 - telegram_bot.core.websocket_request - INFO - Message sent to websocket: 2 / 1 / 346
2024-12-22 15:28:45,119 - aiogram.event - INFO - Update id=166847841 is handled. Duration 281 ms by bot id=7101171025
2024-12-22 15:29:03,720 - telegram_bot.core.websocket_request - INFO - Message sent to websocket: 2 / 1 / 436
2024-12-22 15:29:03,884 - aiogram.event - INFO - Update id=166847842 is handled. Duration 171 ms by bot id=7101171025
2024-12-22 15:43:41,067 - telegram_bot.core.websocket_request - INFO - Message sent to websocket: 2 / 1 / 3465
2024-12-22 15:43:41,298 - aiogram.event - INFO - Update id=166847843 is handled. Duration 237 ms by bot id=7101171025
2024-12-22 15:44:11,054 - telegram_bot.core.websocket_request - INFO - Message sent to websocket: 2 / 1 / 23346
2024-12-22 15:44:11,217 - aiogram.event - INFO - Update id=166847844 is handled. Duration 169 ms by bot id=7101171025
2024-12-22 15:53:40,176 - telegram_bot.core.websocket_request - INFO - Message sent to websocket: 2 / 1 / 4565\
2024-12-22 15:53:40,449 - aiogram.event - INFO - Update id=166847845 is handled. Duration 280 ms by bot id=7101171025
2024-12-22 15:54:16,439 - telegram_bot.core.websocket_request - INFO - Message sent to websocket: 2 / 1 / 346
2024-12-22 15:54:16,601 - aiogram.event - INFO - Update id=166847846 is handled. Duration 169 ms by bot id=7101171025
2024-12-22 15:56:17,443 - telegram_bot.core.websocket_request - INFO - Message sent to websocket: 2 / 1 / 235
2024-12-22 15:56:17,704 - aiogram.event - INFO - Update id=166847847 is handled. Duration 272 ms by bot id=7101171025
2024-12-22 16:06:50,121 - aiogram.dispatcher - INFO - Start polling
2024-12-22 16:06:50,158 - aiogram.dispatcher - INFO - Run polling for bot @dofgd345borbot id=7101171025 - 'bobr123'
2024-12-22 16:06:52,421 - telegram_bot.core.websocket_request - INFO - Message sent to websocket: 2 / 1 / 234
2024-12-22 16:06:52,632 - aiogram.event - INFO - Update id=166847850 is handled. Duration 219 ms by bot id=7101171025
2024-12-22 16:10:47,967 - telegram_bot.core.websocket_request - INFO - Message sent to websocket: 2 / 1 / 235
2024-12-22 16:10:48,216 - aiogram.event - INFO - Update id=166847851 is handled. Duration 255 ms by bot id=7101171025
2024-12-22 16:10:51,127 - telegram_bot.core.websocket_request - INFO - Message sent to websocket: 2 / 1 / 345
2024-12-22 16:10:51,186 - aiogram.event - INFO - Update id=166847852 is handled. Duration 65 ms by bot id=7101171025
2024-12-22 20:38:17,232 - aiogram.dispatcher - INFO - Start polling
2024-12-22 20:38:17,279 - aiogram.dispatcher - INFO - Run polling for bot @dofgd345borbot id=7101171025 - 'bobr123'
2024-12-22 20:41:26,883 - telegram_bot.core.websocket_request - INFO - Message sent to websocket: 2 / 1 / test
2024-12-22 20:41:27,066 - aiogram.event - INFO - Update id=166847853 is handled. Duration 206 ms by bot id=7101171025
2024-12-23 05:53:20,089 - aiogram.dispatcher - INFO - Start polling
2024-12-23 05:53:20,135 - aiogram.dispatcher - INFO - Run polling for bot @dofgd345borbot id=7101171025 - 'bobr123'
2024-12-23 05:53:22,276 - telegram_bot.core.websocket_request - INFO - Message sent to websocket: 2 / 1 / hello
2024-12-23 05:53:22,459 - aiogram.event - INFO - Update id=166847855 is handled. Duration 192 ms by bot id=7101171025
2024-12-23 05:58:41,158 - telegram_bot.core.websocket_request - INFO - Message sent to websocket: 2 / 1 / test
2024-12-23 05:58:41,327 - aiogram.event - INFO - Update id=166847856 is handled. Duration 177 ms by bot id=7101171025
2024-12-23 05:59:07,325 - telegram_bot.core.websocket_request - INFO - Message sent to websocket: 2 / 1 / 235
2024-12-23 05:59:07,492 - aiogram.event - INFO - Update id=166847857 is handled. Duration 173 ms by bot id=7101171025
2024-12-23 06:58:17,605 - aiogram.dispatcher - INFO - Start polling
2024-12-23 06:58:17,643 - aiogram.dispatcher - INFO - Run polling for bot @dofgd345borbot id=7101171025 - 'bobr123'
2024-12-23 06:58:23,241 - telegram_bot.core.websocket_request - INFO - Message sent to websocket: 2 / 1 / 4365
2024-12-23 06:58:23,422 - aiogram.event - INFO - Update id=166847858 is handled. Duration 189 ms by bot id=7101171025
2024-12-23 06:59:52,573 - aiogram.event - INFO - Update id=166847859 is handled. Duration 195 ms by bot id=7101171025
2024-12-23 06:59:55,111 - telegram_bot.core.websocket_request - INFO - Message sent to websocket: 3 / 2 / test
2024-12-23 06:59:55,172 - aiogram.event - INFO - Update id=166847860 is handled. Duration 126 ms by bot id=7101171025
2024-12-23 07:09:36,348 - telegram_bot.core.websocket_request - INFO - Message sent to websocket: 3 / 2 / 6526
2024-12-23 07:09:36,525 - aiogram.event - INFO - Update id=166847861 is handled. Duration 195 ms by bot id=7101171025
2024-12-23 07:09:44,146 - telegram_bot.core.websocket_request - INFO - Message sent to websocket: 3 / 2 / tes
2024-12-23 07:09:44,215 - aiogram.event - INFO - Update id=166847862 is handled. Duration 84 ms by bot id=7101171025
2024-12-23 07:18:21,057 - telegram_bot.core.websocket_request - INFO - Message sent to websocket: 2 / 1 / est
2024-12-23 07:18:21,228 - aiogram.event - INFO - Update id=166847863 is handled. Duration 177 ms by bot id=7101171025
2024-12-23 07:18:27,207 - telegram_bot.core.websocket_request - INFO - Message sent to websocket: 2 / 1 / 123
2024-12-23 07:18:27,258 - aiogram.event - INFO - Update id=166847864 is handled. Duration 57 ms by bot id=7101171025
2024-12-23 07:19:01,034 - telegram_bot.core.websocket_request - INFO - Message sent to websocket: 2 / 1 / test1
2024-12-23 07:19:01,263 - aiogram.event - INFO - Update id=166847865 is handled. Duration 236 ms by bot id=7101171025
2024-12-23 07:28:40,517 - telegram_bot.core.websocket_request - INFO - Message sent to websocket: 4 / 1 / 234
2024-12-23 07:28:40,649 - aiogram.event - INFO - Update id=166847866 is handled. Duration 356 ms by bot id=7101171025
2024-12-23 07:28:54,769 - telegram_bot.core.websocket_request - INFO - Message sent to websocket: 5 / 1 / 2354
2024-12-23 07:28:54,873 - aiogram.event - INFO - Update id=166847867 is handled. Duration 205 ms by bot id=7101171025
2024-12-23 07:39:43,841 - telegram_bot.core.websocket_request - INFO - Message sent to websocket: 5 / 1 / 546
2024-12-23 07:39:44,016 - aiogram.event - INFO - Update id=166847868 is handled. Duration 182 ms by bot id=7101171025
2024-12-23 07:40:32,571 - telegram_bot.core.websocket_request - INFO - Message sent to websocket: 5 / 1 / 234
2024-12-23 07:40:32,749 - aiogram.event - INFO - Update id=166847869 is handled. Duration 183 ms by bot id=7101171025
2024-12-23 07:58:56,586 - telegram_bot.core.websocket_request - INFO - Message sent to websocket: 5 / 1 / 234
2024-12-23 07:58:56,781 - aiogram.event - INFO - Update id=166847870 is handled. Duration 201 ms by bot id=7101171025
2024-12-23 07:59:14,719 - telegram_bot.core.websocket_request - INFO - Message sent to websocket: 5 / 1 / 345
2024-12-23 07:59:14,889 - aiogram.event - INFO - Update id=166847871 is handled. Duration 181 ms by bot id=7101171025
2024-12-23 07:59:34,140 - telegram_bot.core.websocket_request - INFO - Message sent to websocket: 5 / 1 / 324
2024-12-23 07:59:34,322 - aiogram.event - INFO - Update id=166847872 is handled. Duration 187 ms by bot id=7101171025
2024-12-23 08:00:33,314 - telegram_bot.core.websocket_request - INFO - Message sent to websocket: 5 / 1 / 345
2024-12-23 08:00:33,504 - aiogram.event - INFO - Update id=166847873 is handled. Duration 195 ms by bot id=7101171025
2024-12-23 08:01:18,792 - telegram_bot.core.websocket_request - INFO - Message sent to websocket: 5 / 1 / 345
2024-12-23 08:01:18,978 - aiogram.event - INFO - Update id=166847874 is handled. Duration 191 ms by bot id=7101171025
2024-12-23 08:03:24,081 - telegram_bot.core.websocket_request - INFO - Message sent to websocket: 5 / 1 / Так, можна
2024-12-23 08:03:24,253 - aiogram.event - INFO - Update id=166847875 is handled. Duration 178 ms by bot id=7101171025
2024-12-23 08:04:07,050 - telegram_bot.core.websocket_request - INFO - Message sent to websocket: 5 / 1 / 234
2024-12-23 08:04:07,222 - aiogram.event - INFO - Update id=166847876 is handled. Duration 179 ms by bot id=7101171025
2024-12-23 08:04:48,667 - telegram_bot.core.websocket_request - INFO - Message sent to websocket: 5 / 1 / 234
2024-12-23 08:04:48,819 - aiogram.event - INFO - Update id=166847877 is handled. Duration 158 ms by bot id=7101171025
2024-12-23 08:06:40,327 - telegram_bot.core.websocket_request - INFO - Message sent to websocket: 6 / 1 / 234
2024-12-23 08:06:40,432 - aiogram.event - INFO - Update id=166847878 is handled. Duration 290 ms by bot id=7101171025
2024-12-23 08:07:36,123 - telegram_bot.core.websocket_request - INFO - Message sent to websocket: 6 / 1 / 234
2024-12-23 08:07:36,273 - aiogram.event - INFO - Update id=166847879 is handled. Duration 156 ms by bot id=7101171025
2024-12-23 08:13:16,605 - telegram_bot.core.websocket_request - INFO - Message sent to websocket: 7 / 2 / 124
2024-12-23 08:13:16,671 - aiogram.event - INFO - Update id=166847880 is handled. Duration 262 ms by bot id=7101171025
2024-12-23 10:58:32,543 - aiogram.dispatcher - INFO - Start polling
2024-12-23 10:58:32,578 - aiogram.dispatcher - INFO - Run polling for bot @dofgd345borbot id=7101171025 - 'bobr123'
2024-12-23 10:58:34,292 - telegram_bot.core.websocket_request - INFO - Message sent to websocket: 7 / 2 / 2354
2024-12-23 10:58:34,473 - aiogram.event - INFO - Update id=166847883 is handled. Duration 196 ms by bot id=7101171025
2024-12-23 10:59:33,056 - telegram_bot.core.websocket_request - INFO - Message sent to websocket: 8 / 2 / hello
2024-12-23 10:59:33,207 - aiogram.event - INFO - Update id=166847884 is handled. Duration 436 ms by bot id=7101171025
2024-12-23 12:49:00,334 - telegram_bot.core.websocket_request - INFO - Message sent to websocket: 9 / 1 / test
2024-12-23 12:49:00,393 - aiogram.event - INFO - Update id=166847885 is handled. Duration 249 ms by bot id=7101171025
2024-12-23 12:58:47,606 - aiogram.dispatcher - WARNING - Received SIGINT signal
2024-12-23 12:58:47,606 - aiogram.dispatcher - INFO - Polling stopped for bot @dofgd345borbot id=7101171025 - 'bobr123'
2024-12-23 12:58:47,607 - aiogram.dispatcher - INFO - Polling stopped
2024-12-23 12:58:50,520 - aiogram.dispatcher - INFO - Start polling
2024-12-23 12:58:50,582 - aiogram.dispatcher - INFO - Run polling for bot @dofgd345borbot id=7101171025 - 'bobr123'
2024-12-23 13:09:04,804 - aiogram.dispatcher - WARNING - Received SIGINT signal
2024-12-23 13:09:04,804 - aiogram.dispatcher - INFO - Polling stopped for bot @dofgd345borbot id=7101171025 - 'bobr123'
2024-12-23 13:09:04,804 - aiogram.dispatcher - INFO - Polling stopped
2024-12-23 13:09:07,743 - aiogram.dispatcher - INFO - Start polling
2024-12-23 13:09:07,775 - aiogram.dispatcher - INFO - Run polling for bot @dofgd345borbot id=7101171025 - 'bobr123'
2024-12-23 13:09:11,993 - aiogram.event - INFO - Update id=166847886 is handled. Duration 195 ms by bot id=7101171025
2024-12-23 13:09:13,479 - telegram_bot.core.websocket_request - INFO - Message sent to websocket: 9 / 1 / 123
2024-12-23 13:09:13,575 - aiogram.event - INFO - Update id=166847887 is handled. Duration 99 ms by bot id=7101171025
2024-12-23 13:12:12,717 - telegram_bot.core.websocket_request - ERROR - ##################################################
2024-12-23 13:12:12,717 - telegram_bot.core.websocket_request - ERROR - Send to websocket: Cannot connect to host 127.0.0.1:8000 ssl:default [Connect call failed ('127.0.0.1', 8000)]
2024-12-23 13:12:12,719 - telegram_bot.core.websocket_request - ERROR - Traceback (most recent call last):
  File "/home/bybr/Desktop/english_bot/.venv/lib/python3.12/site-packages/aiohttp/connector.py", line 1109, in _wrap_create_connection
    sock = await aiohappyeyeballs.start_connection(
           ^^^^^^^^^^^^^^^^^^^^^^^^^^^^^^^^^^^^^^^^
  File "/home/bybr/Desktop/english_bot/.venv/lib/python3.12/site-packages/aiohappyeyeballs/impl.py", line 104, in start_connection
    raise first_exception
  File "/home/bybr/Desktop/english_bot/.venv/lib/python3.12/site-packages/aiohappyeyeballs/impl.py", line 82, in start_connection
    sock = await _connect_sock(
           ^^^^^^^^^^^^^^^^^^^^
  File "/home/bybr/Desktop/english_bot/.venv/lib/python3.12/site-packages/aiohappyeyeballs/impl.py", line 174, in _connect_sock
    await loop.sock_connect(sock, address)
  File "/usr/lib/python3.12/asyncio/selector_events.py", line 651, in sock_connect
    return await fut
           ^^^^^^^^^
  File "/usr/lib/python3.12/asyncio/selector_events.py", line 691, in _sock_connect_cb
    raise OSError(err, f'Connect call failed {address}')
ConnectionRefusedError: [Errno 111] Connect call failed ('127.0.0.1', 8000)

The above exception was the direct cause of the following exception:

Traceback (most recent call last):
  File "/home/bybr/Desktop/english_bot/telegram_bot/core/websocket_request.py", line 17, in send_to_websocket
    async with session.ws_connect(f"ws://{domain}/ws/chat/{chat_id}/") as ws:
  File "/home/bybr/Desktop/english_bot/.venv/lib/python3.12/site-packages/aiohttp/client.py", line 1360, in __aenter__
    self._resp: _RetType = await self._coro
                           ^^^^^^^^^^^^^^^^
  File "/home/bybr/Desktop/english_bot/.venv/lib/python3.12/site-packages/aiohttp/client.py", line 938, in _ws_connect
    resp = await self.request(
           ^^^^^^^^^^^^^^^^^^^
  File "/home/bybr/Desktop/english_bot/.venv/lib/python3.12/site-packages/aiohttp/client.py", line 663, in _request
    conn = await self._connector.connect(
           ^^^^^^^^^^^^^^^^^^^^^^^^^^^^^^
  File "/home/bybr/Desktop/english_bot/.venv/lib/python3.12/site-packages/aiohttp/connector.py", line 538, in connect
    proto = await self._create_connection(req, traces, timeout)
            ^^^^^^^^^^^^^^^^^^^^^^^^^^^^^^^^^^^^^^^^^^^^^^^^^^^
  File "/home/bybr/Desktop/english_bot/.venv/lib/python3.12/site-packages/aiohttp/connector.py", line 1050, in _create_connection
    _, proto = await self._create_direct_connection(req, traces, timeout)
               ^^^^^^^^^^^^^^^^^^^^^^^^^^^^^^^^^^^^^^^^^^^^^^^^^^^^^^^^^^
  File "/home/bybr/Desktop/english_bot/.venv/lib/python3.12/site-packages/aiohttp/connector.py", line 1384, in _create_direct_connection
    raise last_exc
  File "/home/bybr/Desktop/english_bot/.venv/lib/python3.12/site-packages/aiohttp/connector.py", line 1353, in _create_direct_connection
    transp, proto = await self._wrap_create_connection(
                    ^^^^^^^^^^^^^^^^^^^^^^^^^^^^^^^^^^^
  File "/home/bybr/Desktop/english_bot/.venv/lib/python3.12/site-packages/aiohttp/connector.py", line 1124, in _wrap_create_connection
    raise client_error(req.connection_key, exc) from exc
aiohttp.client_exceptions.ClientConnectorError: Cannot connect to host 127.0.0.1:8000 ssl:default [Connect call failed ('127.0.0.1', 8000)]

2024-12-23 13:12:12,719 - telegram_bot.core.websocket_request - ERROR - ##################################################
2024-12-23 13:12:12,907 - aiogram.event - INFO - Update id=166847888 is handled. Duration 192 ms by bot id=7101171025
2024-12-23 13:12:16,696 - telegram_bot.core.websocket_request - ERROR - ##################################################
2024-12-23 13:12:16,696 - telegram_bot.core.websocket_request - ERROR - Send to websocket: Cannot connect to host 127.0.0.1:8000 ssl:default [Connect call failed ('127.0.0.1', 8000)]
2024-12-23 13:12:16,697 - telegram_bot.core.websocket_request - ERROR - Traceback (most recent call last):
  File "/home/bybr/Desktop/english_bot/.venv/lib/python3.12/site-packages/aiohttp/connector.py", line 1109, in _wrap_create_connection
    sock = await aiohappyeyeballs.start_connection(
           ^^^^^^^^^^^^^^^^^^^^^^^^^^^^^^^^^^^^^^^^
  File "/home/bybr/Desktop/english_bot/.venv/lib/python3.12/site-packages/aiohappyeyeballs/impl.py", line 104, in start_connection
    raise first_exception
  File "/home/bybr/Desktop/english_bot/.venv/lib/python3.12/site-packages/aiohappyeyeballs/impl.py", line 82, in start_connection
    sock = await _connect_sock(
           ^^^^^^^^^^^^^^^^^^^^
  File "/home/bybr/Desktop/english_bot/.venv/lib/python3.12/site-packages/aiohappyeyeballs/impl.py", line 174, in _connect_sock
    await loop.sock_connect(sock, address)
  File "/usr/lib/python3.12/asyncio/selector_events.py", line 651, in sock_connect
    return await fut
           ^^^^^^^^^
  File "/usr/lib/python3.12/asyncio/selector_events.py", line 691, in _sock_connect_cb
    raise OSError(err, f'Connect call failed {address}')
ConnectionRefusedError: [Errno 111] Connect call failed ('127.0.0.1', 8000)

The above exception was the direct cause of the following exception:

Traceback (most recent call last):
  File "/home/bybr/Desktop/english_bot/telegram_bot/core/websocket_request.py", line 17, in send_to_websocket
    async with session.ws_connect(f"ws://{domain}/ws/chat/{chat_id}/") as ws:
  File "/home/bybr/Desktop/english_bot/.venv/lib/python3.12/site-packages/aiohttp/client.py", line 1360, in __aenter__
    self._resp: _RetType = await self._coro
                           ^^^^^^^^^^^^^^^^
  File "/home/bybr/Desktop/english_bot/.venv/lib/python3.12/site-packages/aiohttp/client.py", line 938, in _ws_connect
    resp = await self.request(
           ^^^^^^^^^^^^^^^^^^^
  File "/home/bybr/Desktop/english_bot/.venv/lib/python3.12/site-packages/aiohttp/client.py", line 663, in _request
    conn = await self._connector.connect(
           ^^^^^^^^^^^^^^^^^^^^^^^^^^^^^^
  File "/home/bybr/Desktop/english_bot/.venv/lib/python3.12/site-packages/aiohttp/connector.py", line 538, in connect
    proto = await self._create_connection(req, traces, timeout)
            ^^^^^^^^^^^^^^^^^^^^^^^^^^^^^^^^^^^^^^^^^^^^^^^^^^^
  File "/home/bybr/Desktop/english_bot/.venv/lib/python3.12/site-packages/aiohttp/connector.py", line 1050, in _create_connection
    _, proto = await self._create_direct_connection(req, traces, timeout)
               ^^^^^^^^^^^^^^^^^^^^^^^^^^^^^^^^^^^^^^^^^^^^^^^^^^^^^^^^^^
  File "/home/bybr/Desktop/english_bot/.venv/lib/python3.12/site-packages/aiohttp/connector.py", line 1384, in _create_direct_connection
    raise last_exc
  File "/home/bybr/Desktop/english_bot/.venv/lib/python3.12/site-packages/aiohttp/connector.py", line 1353, in _create_direct_connection
    transp, proto = await self._wrap_create_connection(
                    ^^^^^^^^^^^^^^^^^^^^^^^^^^^^^^^^^^^
  File "/home/bybr/Desktop/english_bot/.venv/lib/python3.12/site-packages/aiohttp/connector.py", line 1124, in _wrap_create_connection
    raise client_error(req.connection_key, exc) from exc
aiohttp.client_exceptions.ClientConnectorError: Cannot connect to host 127.0.0.1:8000 ssl:default [Connect call failed ('127.0.0.1', 8000)]

2024-12-23 13:12:16,697 - telegram_bot.core.websocket_request - ERROR - ##################################################
2024-12-23 13:12:16,756 - aiogram.event - INFO - Update id=166847889 is handled. Duration 61 ms by bot id=7101171025
2024-12-23 13:12:34,880 - telegram_bot.core.websocket_request - INFO - Message sent to websocket: 9 / 1 / 123
2024-12-23 13:12:35,100 - aiogram.event - INFO - Update id=166847890 is handled. Duration 239 ms by bot id=7101171025
2024-12-23 13:13:32,414 - telegram_bot.core.websocket_request - INFO - Message sent to websocket: 9 / 1 / 123
2024-12-23 13:13:32,594 - aiogram.event - INFO - Update id=166847891 is handled. Duration 188 ms by bot id=7101171025
2024-12-23 13:13:53,236 - telegram_bot.core.websocket_request - INFO - Message sent to websocket: 9 / 1 / 234
2024-12-23 13:13:53,436 - aiogram.event - INFO - Update id=166847892 is handled. Duration 208 ms by bot id=7101171025
2024-12-23 13:14:35,949 - telegram_bot.core.websocket_request - INFO - Message sent to websocket: 9 / 1 / 123
2024-12-23 13:14:36,174 - aiogram.event - INFO - Update id=166847893 is handled. Duration 229 ms by bot id=7101171025
2024-12-23 13:15:39,878 - telegram_bot.core.websocket_request - INFO - Message sent to websocket: 9 / 1 / 123
2024-12-23 13:15:40,051 - aiogram.event - INFO - Update id=166847894 is handled. Duration 194 ms by bot id=7101171025
2024-12-23 13:19:03,355 - aiogram.dispatcher - WARNING - Received SIGINT signal
2024-12-23 13:19:03,355 - aiogram.dispatcher - INFO - Polling stopped for bot @dofgd345borbot id=7101171025 - 'bobr123'
2024-12-23 13:19:03,355 - aiogram.dispatcher - INFO - Polling stopped
2024-12-23 13:19:06,313 - aiogram.dispatcher - INFO - Start polling
2024-12-23 13:19:06,349 - aiogram.dispatcher - INFO - Run polling for bot @dofgd345borbot id=7101171025 - 'bobr123'
2024-12-23 13:19:11,493 - aiogram.event - INFO - Update id=166847895 is not handled. Duration 0 ms by bot id=7101171025
2024-12-23 13:19:15,786 - aiogram.event - INFO - Update id=166847896 is not handled. Duration 0 ms by bot id=7101171025
2024-12-23 13:19:19,907 - aiogram.event - INFO - Update id=166847897 is not handled. Duration 0 ms by bot id=7101171025
2024-12-23 13:19:29,340 - aiogram.event - INFO - Update id=166847898 is not handled. Duration 0 ms by bot id=7101171025
2024-12-23 13:19:38,583 - aiogram.event - INFO - Update id=166847899 is handled. Duration 184 ms by bot id=7101171025
2024-12-23 13:19:39,243 - telegram_bot.core.websocket_request - INFO - Message sent to websocket: 9 / 1 / 123
2024-12-23 13:19:39,298 - aiogram.event - INFO - Update id=166847900 is handled. Duration 62 ms by bot id=7101171025
2024-12-23 13:20:16,169 - telegram_bot.core.websocket_request - INFO - Message sent to websocket: 9 / 1 / 123
2024-12-23 13:20:16,416 - aiogram.event - INFO - Update id=166847901 is handled. Duration 255 ms by bot id=7101171025
2024-12-23 13:20:32,599 - telegram_bot.core.websocket_request - INFO - Message sent to websocket: 9 / 1 / 123
2024-12-23 13:20:32,771 - aiogram.event - INFO - Update id=166847902 is handled. Duration 181 ms by bot id=7101171025
2024-12-23 13:20:43,492 - telegram_bot.core.websocket_request - INFO - Message sent to websocket: 9 / 1 / 123
2024-12-23 13:20:43,633 - aiogram.event - INFO - Update id=166847903 is handled. Duration 148 ms by bot id=7101171025
2024-12-23 13:20:50,642 - telegram_bot.core.websocket_request - ERROR - ##################################################
2024-12-23 13:20:50,642 - telegram_bot.core.websocket_request - ERROR - Send to websocket: Cannot connect to host 127.0.0.1:8000 ssl:default [Connect call failed ('127.0.0.1', 8000)]
2024-12-23 13:20:50,644 - telegram_bot.core.websocket_request - ERROR - Traceback (most recent call last):
  File "/home/bybr/Desktop/english_bot/.venv/lib/python3.12/site-packages/aiohttp/connector.py", line 1109, in _wrap_create_connection
    sock = await aiohappyeyeballs.start_connection(
           ^^^^^^^^^^^^^^^^^^^^^^^^^^^^^^^^^^^^^^^^
  File "/home/bybr/Desktop/english_bot/.venv/lib/python3.12/site-packages/aiohappyeyeballs/impl.py", line 104, in start_connection
    raise first_exception
  File "/home/bybr/Desktop/english_bot/.venv/lib/python3.12/site-packages/aiohappyeyeballs/impl.py", line 82, in start_connection
    sock = await _connect_sock(
           ^^^^^^^^^^^^^^^^^^^^
  File "/home/bybr/Desktop/english_bot/.venv/lib/python3.12/site-packages/aiohappyeyeballs/impl.py", line 174, in _connect_sock
    await loop.sock_connect(sock, address)
  File "/usr/lib/python3.12/asyncio/selector_events.py", line 651, in sock_connect
    return await fut
           ^^^^^^^^^
  File "/usr/lib/python3.12/asyncio/selector_events.py", line 691, in _sock_connect_cb
    raise OSError(err, f'Connect call failed {address}')
ConnectionRefusedError: [Errno 111] Connect call failed ('127.0.0.1', 8000)

The above exception was the direct cause of the following exception:

Traceback (most recent call last):
  File "/home/bybr/Desktop/english_bot/telegram_bot/core/websocket_request.py", line 17, in send_to_websocket
    async with session.ws_connect(f"ws://{domain}/ws/chat/{chat_id}/") as ws:
  File "/home/bybr/Desktop/english_bot/.venv/lib/python3.12/site-packages/aiohttp/client.py", line 1360, in __aenter__
    self._resp: _RetType = await self._coro
                           ^^^^^^^^^^^^^^^^
  File "/home/bybr/Desktop/english_bot/.venv/lib/python3.12/site-packages/aiohttp/client.py", line 938, in _ws_connect
    resp = await self.request(
           ^^^^^^^^^^^^^^^^^^^
  File "/home/bybr/Desktop/english_bot/.venv/lib/python3.12/site-packages/aiohttp/client.py", line 663, in _request
    conn = await self._connector.connect(
           ^^^^^^^^^^^^^^^^^^^^^^^^^^^^^^
  File "/home/bybr/Desktop/english_bot/.venv/lib/python3.12/site-packages/aiohttp/connector.py", line 538, in connect
    proto = await self._create_connection(req, traces, timeout)
            ^^^^^^^^^^^^^^^^^^^^^^^^^^^^^^^^^^^^^^^^^^^^^^^^^^^
  File "/home/bybr/Desktop/english_bot/.venv/lib/python3.12/site-packages/aiohttp/connector.py", line 1050, in _create_connection
    _, proto = await self._create_direct_connection(req, traces, timeout)
               ^^^^^^^^^^^^^^^^^^^^^^^^^^^^^^^^^^^^^^^^^^^^^^^^^^^^^^^^^^
  File "/home/bybr/Desktop/english_bot/.venv/lib/python3.12/site-packages/aiohttp/connector.py", line 1384, in _create_direct_connection
    raise last_exc
  File "/home/bybr/Desktop/english_bot/.venv/lib/python3.12/site-packages/aiohttp/connector.py", line 1353, in _create_direct_connection
    transp, proto = await self._wrap_create_connection(
                    ^^^^^^^^^^^^^^^^^^^^^^^^^^^^^^^^^^^
  File "/home/bybr/Desktop/english_bot/.venv/lib/python3.12/site-packages/aiohttp/connector.py", line 1124, in _wrap_create_connection
    raise client_error(req.connection_key, exc) from exc
aiohttp.client_exceptions.ClientConnectorError: Cannot connect to host 127.0.0.1:8000 ssl:default [Connect call failed ('127.0.0.1', 8000)]

2024-12-23 13:20:50,644 - telegram_bot.core.websocket_request - ERROR - ##################################################
2024-12-23 13:20:50,719 - aiogram.event - INFO - Update id=166847904 is handled. Duration 78 ms by bot id=7101171025
2024-12-23 13:20:51,721 - telegram_bot.core.websocket_request - INFO - Message sent to websocket: 9 / 1 / 123
2024-12-23 13:20:51,777 - aiogram.event - INFO - Update id=166847905 is handled. Duration 64 ms by bot id=7101171025
2024-12-23 13:22:27,665 - telegram_bot.core.websocket_request - INFO - Message sent to websocket: 9 / 1 / 123
2024-12-23 13:22:27,849 - aiogram.event - INFO - Update id=166847906 is handled. Duration 193 ms by bot id=7101171025
2024-12-23 13:22:51,140 - telegram_bot.core.websocket_request - INFO - Message sent to websocket: 9 / 1 / 123
2024-12-23 13:22:51,312 - aiogram.event - INFO - Update id=166847907 is handled. Duration 180 ms by bot id=7101171025
2024-12-23 13:23:03,630 - telegram_bot.core.websocket_request - INFO - Message sent to websocket: 9 / 1 / 123
2024-12-23 13:23:03,751 - aiogram.event - INFO - Update id=166847908 is handled. Duration 130 ms by bot id=7101171025
2024-12-23 13:23:34,898 - telegram_bot.core.websocket_request - INFO - Message sent to websocket: 9 / 1 / 123
2024-12-23 13:23:35,138 - aiogram.event - INFO - Update id=166847909 is handled. Duration 249 ms by bot id=7101171025
2024-12-23 13:23:50,567 - telegram_bot.core.websocket_request - INFO - Message sent to websocket: 9 / 1 / 123
2024-12-23 13:23:50,742 - aiogram.event - INFO - Update id=166847910 is handled. Duration 184 ms by bot id=7101171025
2024-12-23 13:24:11,077 - telegram_bot.core.websocket_request - ERROR - ##################################################
2024-12-23 13:24:11,077 - telegram_bot.core.websocket_request - ERROR - Send to websocket: Cannot connect to host 127.0.0.1:8000 ssl:default [Connect call failed ('127.0.0.1', 8000)]
2024-12-23 13:24:11,078 - telegram_bot.core.websocket_request - ERROR - Traceback (most recent call last):
  File "/home/bybr/Desktop/english_bot/.venv/lib/python3.12/site-packages/aiohttp/connector.py", line 1109, in _wrap_create_connection
    sock = await aiohappyeyeballs.start_connection(
           ^^^^^^^^^^^^^^^^^^^^^^^^^^^^^^^^^^^^^^^^
  File "/home/bybr/Desktop/english_bot/.venv/lib/python3.12/site-packages/aiohappyeyeballs/impl.py", line 104, in start_connection
    raise first_exception
  File "/home/bybr/Desktop/english_bot/.venv/lib/python3.12/site-packages/aiohappyeyeballs/impl.py", line 82, in start_connection
    sock = await _connect_sock(
           ^^^^^^^^^^^^^^^^^^^^
  File "/home/bybr/Desktop/english_bot/.venv/lib/python3.12/site-packages/aiohappyeyeballs/impl.py", line 174, in _connect_sock
    await loop.sock_connect(sock, address)
  File "/usr/lib/python3.12/asyncio/selector_events.py", line 651, in sock_connect
    return await fut
           ^^^^^^^^^
  File "/usr/lib/python3.12/asyncio/selector_events.py", line 691, in _sock_connect_cb
    raise OSError(err, f'Connect call failed {address}')
ConnectionRefusedError: [Errno 111] Connect call failed ('127.0.0.1', 8000)

The above exception was the direct cause of the following exception:

Traceback (most recent call last):
  File "/home/bybr/Desktop/english_bot/telegram_bot/core/websocket_request.py", line 17, in send_to_websocket
    async with session.ws_connect(f"ws://{domain}/ws/chat/{chat_id}/") as ws:
  File "/home/bybr/Desktop/english_bot/.venv/lib/python3.12/site-packages/aiohttp/client.py", line 1360, in __aenter__
    self._resp: _RetType = await self._coro
                           ^^^^^^^^^^^^^^^^
  File "/home/bybr/Desktop/english_bot/.venv/lib/python3.12/site-packages/aiohttp/client.py", line 938, in _ws_connect
    resp = await self.request(
           ^^^^^^^^^^^^^^^^^^^
  File "/home/bybr/Desktop/english_bot/.venv/lib/python3.12/site-packages/aiohttp/client.py", line 663, in _request
    conn = await self._connector.connect(
           ^^^^^^^^^^^^^^^^^^^^^^^^^^^^^^
  File "/home/bybr/Desktop/english_bot/.venv/lib/python3.12/site-packages/aiohttp/connector.py", line 538, in connect
    proto = await self._create_connection(req, traces, timeout)
            ^^^^^^^^^^^^^^^^^^^^^^^^^^^^^^^^^^^^^^^^^^^^^^^^^^^
  File "/home/bybr/Desktop/english_bot/.venv/lib/python3.12/site-packages/aiohttp/connector.py", line 1050, in _create_connection
    _, proto = await self._create_direct_connection(req, traces, timeout)
               ^^^^^^^^^^^^^^^^^^^^^^^^^^^^^^^^^^^^^^^^^^^^^^^^^^^^^^^^^^
  File "/home/bybr/Desktop/english_bot/.venv/lib/python3.12/site-packages/aiohttp/connector.py", line 1384, in _create_direct_connection
    raise last_exc
  File "/home/bybr/Desktop/english_bot/.venv/lib/python3.12/site-packages/aiohttp/connector.py", line 1353, in _create_direct_connection
    transp, proto = await self._wrap_create_connection(
                    ^^^^^^^^^^^^^^^^^^^^^^^^^^^^^^^^^^^
  File "/home/bybr/Desktop/english_bot/.venv/lib/python3.12/site-packages/aiohttp/connector.py", line 1124, in _wrap_create_connection
    raise client_error(req.connection_key, exc) from exc
aiohttp.client_exceptions.ClientConnectorError: Cannot connect to host 127.0.0.1:8000 ssl:default [Connect call failed ('127.0.0.1', 8000)]

2024-12-23 13:24:11,078 - telegram_bot.core.websocket_request - ERROR - ##################################################
2024-12-23 13:24:11,302 - aiogram.event - INFO - Update id=166847911 is handled. Duration 226 ms by bot id=7101171025
2024-12-23 13:24:12,400 - telegram_bot.core.websocket_request - INFO - Message sent to websocket: 9 / 1 / 123
2024-12-23 13:24:12,576 - aiogram.event - INFO - Update id=166847912 is handled. Duration 184 ms by bot id=7101171025
2024-12-23 13:24:39,392 - telegram_bot.core.websocket_request - INFO - Message sent to websocket: 9 / 1 / 123
2024-12-23 13:24:39,603 - aiogram.event - INFO - Update id=166847913 is handled. Duration 221 ms by bot id=7101171025
2024-12-23 13:25:01,792 - telegram_bot.core.websocket_request - ERROR - ##################################################
2024-12-23 13:25:01,792 - telegram_bot.core.websocket_request - ERROR - Send to websocket: Cannot connect to host 127.0.0.1:8000 ssl:default [Connect call failed ('127.0.0.1', 8000)]
2024-12-23 13:25:01,793 - telegram_bot.core.websocket_request - ERROR - Traceback (most recent call last):
  File "/home/bybr/Desktop/english_bot/.venv/lib/python3.12/site-packages/aiohttp/connector.py", line 1109, in _wrap_create_connection
    sock = await aiohappyeyeballs.start_connection(
           ^^^^^^^^^^^^^^^^^^^^^^^^^^^^^^^^^^^^^^^^
  File "/home/bybr/Desktop/english_bot/.venv/lib/python3.12/site-packages/aiohappyeyeballs/impl.py", line 104, in start_connection
    raise first_exception
  File "/home/bybr/Desktop/english_bot/.venv/lib/python3.12/site-packages/aiohappyeyeballs/impl.py", line 82, in start_connection
    sock = await _connect_sock(
           ^^^^^^^^^^^^^^^^^^^^
  File "/home/bybr/Desktop/english_bot/.venv/lib/python3.12/site-packages/aiohappyeyeballs/impl.py", line 174, in _connect_sock
    await loop.sock_connect(sock, address)
  File "/usr/lib/python3.12/asyncio/selector_events.py", line 651, in sock_connect
    return await fut
           ^^^^^^^^^
  File "/usr/lib/python3.12/asyncio/selector_events.py", line 691, in _sock_connect_cb
    raise OSError(err, f'Connect call failed {address}')
ConnectionRefusedError: [Errno 111] Connect call failed ('127.0.0.1', 8000)

The above exception was the direct cause of the following exception:

Traceback (most recent call last):
  File "/home/bybr/Desktop/english_bot/telegram_bot/core/websocket_request.py", line 17, in send_to_websocket
    async with session.ws_connect(f"ws://{domain}/ws/chat/{chat_id}/") as ws:
  File "/home/bybr/Desktop/english_bot/.venv/lib/python3.12/site-packages/aiohttp/client.py", line 1360, in __aenter__
    self._resp: _RetType = await self._coro
                           ^^^^^^^^^^^^^^^^
  File "/home/bybr/Desktop/english_bot/.venv/lib/python3.12/site-packages/aiohttp/client.py", line 938, in _ws_connect
    resp = await self.request(
           ^^^^^^^^^^^^^^^^^^^
  File "/home/bybr/Desktop/english_bot/.venv/lib/python3.12/site-packages/aiohttp/client.py", line 663, in _request
    conn = await self._connector.connect(
           ^^^^^^^^^^^^^^^^^^^^^^^^^^^^^^
  File "/home/bybr/Desktop/english_bot/.venv/lib/python3.12/site-packages/aiohttp/connector.py", line 538, in connect
    proto = await self._create_connection(req, traces, timeout)
            ^^^^^^^^^^^^^^^^^^^^^^^^^^^^^^^^^^^^^^^^^^^^^^^^^^^
  File "/home/bybr/Desktop/english_bot/.venv/lib/python3.12/site-packages/aiohttp/connector.py", line 1050, in _create_connection
    _, proto = await self._create_direct_connection(req, traces, timeout)
               ^^^^^^^^^^^^^^^^^^^^^^^^^^^^^^^^^^^^^^^^^^^^^^^^^^^^^^^^^^
  File "/home/bybr/Desktop/english_bot/.venv/lib/python3.12/site-packages/aiohttp/connector.py", line 1384, in _create_direct_connection
    raise last_exc
  File "/home/bybr/Desktop/english_bot/.venv/lib/python3.12/site-packages/aiohttp/connector.py", line 1353, in _create_direct_connection
    transp, proto = await self._wrap_create_connection(
                    ^^^^^^^^^^^^^^^^^^^^^^^^^^^^^^^^^^^
  File "/home/bybr/Desktop/english_bot/.venv/lib/python3.12/site-packages/aiohttp/connector.py", line 1124, in _wrap_create_connection
    raise client_error(req.connection_key, exc) from exc
aiohttp.client_exceptions.ClientConnectorError: Cannot connect to host 127.0.0.1:8000 ssl:default [Connect call failed ('127.0.0.1', 8000)]

2024-12-23 13:25:01,793 - telegram_bot.core.websocket_request - ERROR - ##################################################
2024-12-23 13:25:01,981 - aiogram.event - INFO - Update id=166847914 is handled. Duration 190 ms by bot id=7101171025
2024-12-23 13:25:02,797 - telegram_bot.core.websocket_request - ERROR - ##################################################
2024-12-23 13:25:02,797 - telegram_bot.core.websocket_request - ERROR - Send to websocket: Cannot connect to host 127.0.0.1:8000 ssl:default [Connect call failed ('127.0.0.1', 8000)]
2024-12-23 13:25:02,798 - telegram_bot.core.websocket_request - ERROR - Traceback (most recent call last):
  File "/home/bybr/Desktop/english_bot/.venv/lib/python3.12/site-packages/aiohttp/connector.py", line 1109, in _wrap_create_connection
    sock = await aiohappyeyeballs.start_connection(
           ^^^^^^^^^^^^^^^^^^^^^^^^^^^^^^^^^^^^^^^^
  File "/home/bybr/Desktop/english_bot/.venv/lib/python3.12/site-packages/aiohappyeyeballs/impl.py", line 104, in start_connection
    raise first_exception
  File "/home/bybr/Desktop/english_bot/.venv/lib/python3.12/site-packages/aiohappyeyeballs/impl.py", line 82, in start_connection
    sock = await _connect_sock(
           ^^^^^^^^^^^^^^^^^^^^
  File "/home/bybr/Desktop/english_bot/.venv/lib/python3.12/site-packages/aiohappyeyeballs/impl.py", line 174, in _connect_sock
    await loop.sock_connect(sock, address)
  File "/usr/lib/python3.12/asyncio/selector_events.py", line 651, in sock_connect
    return await fut
           ^^^^^^^^^
  File "/usr/lib/python3.12/asyncio/selector_events.py", line 691, in _sock_connect_cb
    raise OSError(err, f'Connect call failed {address}')
ConnectionRefusedError: [Errno 111] Connect call failed ('127.0.0.1', 8000)

The above exception was the direct cause of the following exception:

Traceback (most recent call last):
  File "/home/bybr/Desktop/english_bot/telegram_bot/core/websocket_request.py", line 17, in send_to_websocket
    async with session.ws_connect(f"ws://{domain}/ws/chat/{chat_id}/") as ws:
  File "/home/bybr/Desktop/english_bot/.venv/lib/python3.12/site-packages/aiohttp/client.py", line 1360, in __aenter__
    self._resp: _RetType = await self._coro
                           ^^^^^^^^^^^^^^^^
  File "/home/bybr/Desktop/english_bot/.venv/lib/python3.12/site-packages/aiohttp/client.py", line 938, in _ws_connect
    resp = await self.request(
           ^^^^^^^^^^^^^^^^^^^
  File "/home/bybr/Desktop/english_bot/.venv/lib/python3.12/site-packages/aiohttp/client.py", line 663, in _request
    conn = await self._connector.connect(
           ^^^^^^^^^^^^^^^^^^^^^^^^^^^^^^
  File "/home/bybr/Desktop/english_bot/.venv/lib/python3.12/site-packages/aiohttp/connector.py", line 538, in connect
    proto = await self._create_connection(req, traces, timeout)
            ^^^^^^^^^^^^^^^^^^^^^^^^^^^^^^^^^^^^^^^^^^^^^^^^^^^
  File "/home/bybr/Desktop/english_bot/.venv/lib/python3.12/site-packages/aiohttp/connector.py", line 1050, in _create_connection
    _, proto = await self._create_direct_connection(req, traces, timeout)
               ^^^^^^^^^^^^^^^^^^^^^^^^^^^^^^^^^^^^^^^^^^^^^^^^^^^^^^^^^^
  File "/home/bybr/Desktop/english_bot/.venv/lib/python3.12/site-packages/aiohttp/connector.py", line 1384, in _create_direct_connection
    raise last_exc
  File "/home/bybr/Desktop/english_bot/.venv/lib/python3.12/site-packages/aiohttp/connector.py", line 1353, in _create_direct_connection
    transp, proto = await self._wrap_create_connection(
                    ^^^^^^^^^^^^^^^^^^^^^^^^^^^^^^^^^^^
  File "/home/bybr/Desktop/english_bot/.venv/lib/python3.12/site-packages/aiohttp/connector.py", line 1124, in _wrap_create_connection
    raise client_error(req.connection_key, exc) from exc
aiohttp.client_exceptions.ClientConnectorError: Cannot connect to host 127.0.0.1:8000 ssl:default [Connect call failed ('127.0.0.1', 8000)]

2024-12-23 13:25:02,798 - telegram_bot.core.websocket_request - ERROR - ##################################################
2024-12-23 13:25:02,863 - aiogram.event - INFO - Update id=166847915 is handled. Duration 67 ms by bot id=7101171025
2024-12-23 13:25:03,997 - telegram_bot.core.websocket_request - INFO - Message sent to websocket: 9 / 1 / 123
2024-12-23 13:25:04,075 - aiogram.event - INFO - Update id=166847916 is handled. Duration 85 ms by bot id=7101171025
2024-12-23 13:25:42,707 - telegram_bot.core.websocket_request - INFO - Message sent to websocket: 9 / 1 / 13
2024-12-23 13:25:42,885 - aiogram.event - INFO - Update id=166847917 is handled. Duration 188 ms by bot id=7101171025
2024-12-23 13:25:52,152 - telegram_bot.core.websocket_request - INFO - Message sent to websocket: 9 / 1 / 123
2024-12-23 13:25:52,304 - aiogram.event - INFO - Update id=166847918 is handled. Duration 161 ms by bot id=7101171025
2024-12-23 13:26:15,012 - telegram_bot.core.websocket_request - INFO - Message sent to websocket: 9 / 1 / 123
2024-12-23 13:26:15,212 - aiogram.event - INFO - Update id=166847919 is handled. Duration 208 ms by bot id=7101171025
2024-12-23 13:26:49,912 - telegram_bot.core.websocket_request - ERROR - ##################################################
2024-12-23 13:26:49,912 - telegram_bot.core.websocket_request - ERROR - Send to websocket: Cannot connect to host 127.0.0.1:8000 ssl:default [Connect call failed ('127.0.0.1', 8000)]
2024-12-23 13:26:49,913 - telegram_bot.core.websocket_request - ERROR - Traceback (most recent call last):
  File "/home/bybr/Desktop/english_bot/.venv/lib/python3.12/site-packages/aiohttp/connector.py", line 1109, in _wrap_create_connection
    sock = await aiohappyeyeballs.start_connection(
           ^^^^^^^^^^^^^^^^^^^^^^^^^^^^^^^^^^^^^^^^
  File "/home/bybr/Desktop/english_bot/.venv/lib/python3.12/site-packages/aiohappyeyeballs/impl.py", line 104, in start_connection
    raise first_exception
  File "/home/bybr/Desktop/english_bot/.venv/lib/python3.12/site-packages/aiohappyeyeballs/impl.py", line 82, in start_connection
    sock = await _connect_sock(
           ^^^^^^^^^^^^^^^^^^^^
  File "/home/bybr/Desktop/english_bot/.venv/lib/python3.12/site-packages/aiohappyeyeballs/impl.py", line 174, in _connect_sock
    await loop.sock_connect(sock, address)
  File "/usr/lib/python3.12/asyncio/selector_events.py", line 651, in sock_connect
    return await fut
           ^^^^^^^^^
  File "/usr/lib/python3.12/asyncio/selector_events.py", line 691, in _sock_connect_cb
    raise OSError(err, f'Connect call failed {address}')
ConnectionRefusedError: [Errno 111] Connect call failed ('127.0.0.1', 8000)

The above exception was the direct cause of the following exception:

Traceback (most recent call last):
  File "/home/bybr/Desktop/english_bot/telegram_bot/core/websocket_request.py", line 17, in send_to_websocket
    async with session.ws_connect(f"ws://{domain}/ws/chat/{chat_id}/") as ws:
  File "/home/bybr/Desktop/english_bot/.venv/lib/python3.12/site-packages/aiohttp/client.py", line 1360, in __aenter__
    self._resp: _RetType = await self._coro
                           ^^^^^^^^^^^^^^^^
  File "/home/bybr/Desktop/english_bot/.venv/lib/python3.12/site-packages/aiohttp/client.py", line 938, in _ws_connect
    resp = await self.request(
           ^^^^^^^^^^^^^^^^^^^
  File "/home/bybr/Desktop/english_bot/.venv/lib/python3.12/site-packages/aiohttp/client.py", line 663, in _request
    conn = await self._connector.connect(
           ^^^^^^^^^^^^^^^^^^^^^^^^^^^^^^
  File "/home/bybr/Desktop/english_bot/.venv/lib/python3.12/site-packages/aiohttp/connector.py", line 538, in connect
    proto = await self._create_connection(req, traces, timeout)
            ^^^^^^^^^^^^^^^^^^^^^^^^^^^^^^^^^^^^^^^^^^^^^^^^^^^
  File "/home/bybr/Desktop/english_bot/.venv/lib/python3.12/site-packages/aiohttp/connector.py", line 1050, in _create_connection
    _, proto = await self._create_direct_connection(req, traces, timeout)
               ^^^^^^^^^^^^^^^^^^^^^^^^^^^^^^^^^^^^^^^^^^^^^^^^^^^^^^^^^^
  File "/home/bybr/Desktop/english_bot/.venv/lib/python3.12/site-packages/aiohttp/connector.py", line 1384, in _create_direct_connection
    raise last_exc
  File "/home/bybr/Desktop/english_bot/.venv/lib/python3.12/site-packages/aiohttp/connector.py", line 1353, in _create_direct_connection
    transp, proto = await self._wrap_create_connection(
                    ^^^^^^^^^^^^^^^^^^^^^^^^^^^^^^^^^^^
  File "/home/bybr/Desktop/english_bot/.venv/lib/python3.12/site-packages/aiohttp/connector.py", line 1124, in _wrap_create_connection
    raise client_error(req.connection_key, exc) from exc
aiohttp.client_exceptions.ClientConnectorError: Cannot connect to host 127.0.0.1:8000 ssl:default [Connect call failed ('127.0.0.1', 8000)]

2024-12-23 13:26:49,913 - telegram_bot.core.websocket_request - ERROR - ##################################################
2024-12-23 13:26:50,085 - aiogram.event - INFO - Update id=166847920 is handled. Duration 174 ms by bot id=7101171025
2024-12-23 13:26:51,468 - telegram_bot.core.websocket_request - INFO - Message sent to websocket: 9 / 1 / 123
2024-12-23 13:26:51,578 - aiogram.event - INFO - Update id=166847921 is handled. Duration 119 ms by bot id=7101171025
2024-12-23 13:26:59,245 - telegram_bot.core.websocket_request - ERROR - ##################################################
2024-12-23 13:26:59,245 - telegram_bot.core.websocket_request - ERROR - Send to websocket: Cannot connect to host 127.0.0.1:8000 ssl:default [Connect call failed ('127.0.0.1', 8000)]
2024-12-23 13:26:59,246 - telegram_bot.core.websocket_request - ERROR - Traceback (most recent call last):
  File "/home/bybr/Desktop/english_bot/.venv/lib/python3.12/site-packages/aiohttp/connector.py", line 1109, in _wrap_create_connection
    sock = await aiohappyeyeballs.start_connection(
           ^^^^^^^^^^^^^^^^^^^^^^^^^^^^^^^^^^^^^^^^
  File "/home/bybr/Desktop/english_bot/.venv/lib/python3.12/site-packages/aiohappyeyeballs/impl.py", line 104, in start_connection
    raise first_exception
  File "/home/bybr/Desktop/english_bot/.venv/lib/python3.12/site-packages/aiohappyeyeballs/impl.py", line 82, in start_connection
    sock = await _connect_sock(
           ^^^^^^^^^^^^^^^^^^^^
  File "/home/bybr/Desktop/english_bot/.venv/lib/python3.12/site-packages/aiohappyeyeballs/impl.py", line 174, in _connect_sock
    await loop.sock_connect(sock, address)
  File "/usr/lib/python3.12/asyncio/selector_events.py", line 651, in sock_connect
    return await fut
           ^^^^^^^^^
  File "/usr/lib/python3.12/asyncio/selector_events.py", line 691, in _sock_connect_cb
    raise OSError(err, f'Connect call failed {address}')
ConnectionRefusedError: [Errno 111] Connect call failed ('127.0.0.1', 8000)

The above exception was the direct cause of the following exception:

Traceback (most recent call last):
  File "/home/bybr/Desktop/english_bot/telegram_bot/core/websocket_request.py", line 17, in send_to_websocket
    async with session.ws_connect(f"ws://{domain}/ws/chat/{chat_id}/") as ws:
  File "/home/bybr/Desktop/english_bot/.venv/lib/python3.12/site-packages/aiohttp/client.py", line 1360, in __aenter__
    self._resp: _RetType = await self._coro
                           ^^^^^^^^^^^^^^^^
  File "/home/bybr/Desktop/english_bot/.venv/lib/python3.12/site-packages/aiohttp/client.py", line 938, in _ws_connect
    resp = await self.request(
           ^^^^^^^^^^^^^^^^^^^
  File "/home/bybr/Desktop/english_bot/.venv/lib/python3.12/site-packages/aiohttp/client.py", line 663, in _request
    conn = await self._connector.connect(
           ^^^^^^^^^^^^^^^^^^^^^^^^^^^^^^
  File "/home/bybr/Desktop/english_bot/.venv/lib/python3.12/site-packages/aiohttp/connector.py", line 538, in connect
    proto = await self._create_connection(req, traces, timeout)
            ^^^^^^^^^^^^^^^^^^^^^^^^^^^^^^^^^^^^^^^^^^^^^^^^^^^
  File "/home/bybr/Desktop/english_bot/.venv/lib/python3.12/site-packages/aiohttp/connector.py", line 1050, in _create_connection
    _, proto = await self._create_direct_connection(req, traces, timeout)
               ^^^^^^^^^^^^^^^^^^^^^^^^^^^^^^^^^^^^^^^^^^^^^^^^^^^^^^^^^^
  File "/home/bybr/Desktop/english_bot/.venv/lib/python3.12/site-packages/aiohttp/connector.py", line 1384, in _create_direct_connection
    raise last_exc
  File "/home/bybr/Desktop/english_bot/.venv/lib/python3.12/site-packages/aiohttp/connector.py", line 1353, in _create_direct_connection
    transp, proto = await self._wrap_create_connection(
                    ^^^^^^^^^^^^^^^^^^^^^^^^^^^^^^^^^^^
  File "/home/bybr/Desktop/english_bot/.venv/lib/python3.12/site-packages/aiohttp/connector.py", line 1124, in _wrap_create_connection
    raise client_error(req.connection_key, exc) from exc
aiohttp.client_exceptions.ClientConnectorError: Cannot connect to host 127.0.0.1:8000 ssl:default [Connect call failed ('127.0.0.1', 8000)]

2024-12-23 13:26:59,246 - telegram_bot.core.websocket_request - ERROR - ##################################################
2024-12-23 13:26:59,381 - aiogram.event - INFO - Update id=166847922 is handled. Duration 138 ms by bot id=7101171025
2024-12-23 13:27:00,079 - telegram_bot.core.websocket_request - ERROR - ##################################################
2024-12-23 13:27:00,079 - telegram_bot.core.websocket_request - ERROR - Send to websocket: Cannot connect to host 127.0.0.1:8000 ssl:default [Connect call failed ('127.0.0.1', 8000)]
2024-12-23 13:27:00,080 - telegram_bot.core.websocket_request - ERROR - Traceback (most recent call last):
  File "/home/bybr/Desktop/english_bot/.venv/lib/python3.12/site-packages/aiohttp/connector.py", line 1109, in _wrap_create_connection
    sock = await aiohappyeyeballs.start_connection(
           ^^^^^^^^^^^^^^^^^^^^^^^^^^^^^^^^^^^^^^^^
  File "/home/bybr/Desktop/english_bot/.venv/lib/python3.12/site-packages/aiohappyeyeballs/impl.py", line 104, in start_connection
    raise first_exception
  File "/home/bybr/Desktop/english_bot/.venv/lib/python3.12/site-packages/aiohappyeyeballs/impl.py", line 82, in start_connection
    sock = await _connect_sock(
           ^^^^^^^^^^^^^^^^^^^^
  File "/home/bybr/Desktop/english_bot/.venv/lib/python3.12/site-packages/aiohappyeyeballs/impl.py", line 174, in _connect_sock
    await loop.sock_connect(sock, address)
  File "/usr/lib/python3.12/asyncio/selector_events.py", line 651, in sock_connect
    return await fut
           ^^^^^^^^^
  File "/usr/lib/python3.12/asyncio/selector_events.py", line 691, in _sock_connect_cb
    raise OSError(err, f'Connect call failed {address}')
ConnectionRefusedError: [Errno 111] Connect call failed ('127.0.0.1', 8000)

The above exception was the direct cause of the following exception:

Traceback (most recent call last):
  File "/home/bybr/Desktop/english_bot/telegram_bot/core/websocket_request.py", line 17, in send_to_websocket
    async with session.ws_connect(f"ws://{domain}/ws/chat/{chat_id}/") as ws:
  File "/home/bybr/Desktop/english_bot/.venv/lib/python3.12/site-packages/aiohttp/client.py", line 1360, in __aenter__
    self._resp: _RetType = await self._coro
                           ^^^^^^^^^^^^^^^^
  File "/home/bybr/Desktop/english_bot/.venv/lib/python3.12/site-packages/aiohttp/client.py", line 938, in _ws_connect
    resp = await self.request(
           ^^^^^^^^^^^^^^^^^^^
  File "/home/bybr/Desktop/english_bot/.venv/lib/python3.12/site-packages/aiohttp/client.py", line 663, in _request
    conn = await self._connector.connect(
           ^^^^^^^^^^^^^^^^^^^^^^^^^^^^^^
  File "/home/bybr/Desktop/english_bot/.venv/lib/python3.12/site-packages/aiohttp/connector.py", line 538, in connect
    proto = await self._create_connection(req, traces, timeout)
            ^^^^^^^^^^^^^^^^^^^^^^^^^^^^^^^^^^^^^^^^^^^^^^^^^^^
  File "/home/bybr/Desktop/english_bot/.venv/lib/python3.12/site-packages/aiohttp/connector.py", line 1050, in _create_connection
    _, proto = await self._create_direct_connection(req, traces, timeout)
               ^^^^^^^^^^^^^^^^^^^^^^^^^^^^^^^^^^^^^^^^^^^^^^^^^^^^^^^^^^
  File "/home/bybr/Desktop/english_bot/.venv/lib/python3.12/site-packages/aiohttp/connector.py", line 1384, in _create_direct_connection
    raise last_exc
  File "/home/bybr/Desktop/english_bot/.venv/lib/python3.12/site-packages/aiohttp/connector.py", line 1353, in _create_direct_connection
    transp, proto = await self._wrap_create_connection(
                    ^^^^^^^^^^^^^^^^^^^^^^^^^^^^^^^^^^^
  File "/home/bybr/Desktop/english_bot/.venv/lib/python3.12/site-packages/aiohttp/connector.py", line 1124, in _wrap_create_connection
    raise client_error(req.connection_key, exc) from exc
aiohttp.client_exceptions.ClientConnectorError: Cannot connect to host 127.0.0.1:8000 ssl:default [Connect call failed ('127.0.0.1', 8000)]

2024-12-23 13:27:00,080 - telegram_bot.core.websocket_request - ERROR - ##################################################
2024-12-23 13:27:00,179 - aiogram.event - INFO - Update id=166847923 is handled. Duration 101 ms by bot id=7101171025
2024-12-23 13:27:01,147 - telegram_bot.core.websocket_request - ERROR - ##################################################
2024-12-23 13:27:01,147 - telegram_bot.core.websocket_request - ERROR - Send to websocket: Cannot connect to host 127.0.0.1:8000 ssl:default [Connect call failed ('127.0.0.1', 8000)]
2024-12-23 13:27:01,148 - telegram_bot.core.websocket_request - ERROR - Traceback (most recent call last):
  File "/home/bybr/Desktop/english_bot/.venv/lib/python3.12/site-packages/aiohttp/connector.py", line 1109, in _wrap_create_connection
    sock = await aiohappyeyeballs.start_connection(
           ^^^^^^^^^^^^^^^^^^^^^^^^^^^^^^^^^^^^^^^^
  File "/home/bybr/Desktop/english_bot/.venv/lib/python3.12/site-packages/aiohappyeyeballs/impl.py", line 104, in start_connection
    raise first_exception
  File "/home/bybr/Desktop/english_bot/.venv/lib/python3.12/site-packages/aiohappyeyeballs/impl.py", line 82, in start_connection
    sock = await _connect_sock(
           ^^^^^^^^^^^^^^^^^^^^
  File "/home/bybr/Desktop/english_bot/.venv/lib/python3.12/site-packages/aiohappyeyeballs/impl.py", line 174, in _connect_sock
    await loop.sock_connect(sock, address)
  File "/usr/lib/python3.12/asyncio/selector_events.py", line 651, in sock_connect
    return await fut
           ^^^^^^^^^
  File "/usr/lib/python3.12/asyncio/selector_events.py", line 691, in _sock_connect_cb
    raise OSError(err, f'Connect call failed {address}')
ConnectionRefusedError: [Errno 111] Connect call failed ('127.0.0.1', 8000)

The above exception was the direct cause of the following exception:

Traceback (most recent call last):
  File "/home/bybr/Desktop/english_bot/telegram_bot/core/websocket_request.py", line 17, in send_to_websocket
    async with session.ws_connect(f"ws://{domain}/ws/chat/{chat_id}/") as ws:
  File "/home/bybr/Desktop/english_bot/.venv/lib/python3.12/site-packages/aiohttp/client.py", line 1360, in __aenter__
    self._resp: _RetType = await self._coro
                           ^^^^^^^^^^^^^^^^
  File "/home/bybr/Desktop/english_bot/.venv/lib/python3.12/site-packages/aiohttp/client.py", line 938, in _ws_connect
    resp = await self.request(
           ^^^^^^^^^^^^^^^^^^^
  File "/home/bybr/Desktop/english_bot/.venv/lib/python3.12/site-packages/aiohttp/client.py", line 663, in _request
    conn = await self._connector.connect(
           ^^^^^^^^^^^^^^^^^^^^^^^^^^^^^^
  File "/home/bybr/Desktop/english_bot/.venv/lib/python3.12/site-packages/aiohttp/connector.py", line 538, in connect
    proto = await self._create_connection(req, traces, timeout)
            ^^^^^^^^^^^^^^^^^^^^^^^^^^^^^^^^^^^^^^^^^^^^^^^^^^^
  File "/home/bybr/Desktop/english_bot/.venv/lib/python3.12/site-packages/aiohttp/connector.py", line 1050, in _create_connection
    _, proto = await self._create_direct_connection(req, traces, timeout)
               ^^^^^^^^^^^^^^^^^^^^^^^^^^^^^^^^^^^^^^^^^^^^^^^^^^^^^^^^^^
  File "/home/bybr/Desktop/english_bot/.venv/lib/python3.12/site-packages/aiohttp/connector.py", line 1384, in _create_direct_connection
    raise last_exc
  File "/home/bybr/Desktop/english_bot/.venv/lib/python3.12/site-packages/aiohttp/connector.py", line 1353, in _create_direct_connection
    transp, proto = await self._wrap_create_connection(
                    ^^^^^^^^^^^^^^^^^^^^^^^^^^^^^^^^^^^
  File "/home/bybr/Desktop/english_bot/.venv/lib/python3.12/site-packages/aiohttp/connector.py", line 1124, in _wrap_create_connection
    raise client_error(req.connection_key, exc) from exc
aiohttp.client_exceptions.ClientConnectorError: Cannot connect to host 127.0.0.1:8000 ssl:default [Connect call failed ('127.0.0.1', 8000)]

2024-12-23 13:27:01,148 - telegram_bot.core.websocket_request - ERROR - ##################################################
2024-12-23 13:27:01,241 - aiogram.event - INFO - Update id=166847924 is handled. Duration 95 ms by bot id=7101171025
2024-12-23 13:27:02,145 - telegram_bot.core.websocket_request - INFO - Message sent to websocket: 9 / 1 / 12
2024-12-23 13:27:02,240 - aiogram.event - INFO - Update id=166847925 is handled. Duration 104 ms by bot id=7101171025
2024-12-23 13:27:16,483 - telegram_bot.core.websocket_request - INFO - Message sent to websocket: 9 / 1 / 123
2024-12-23 13:27:16,537 - aiogram.event - INFO - Update id=166847926 is handled. Duration 62 ms by bot id=7101171025
2024-12-23 13:28:38,753 - telegram_bot.core.websocket_request - INFO - Message sent to websocket: 9 / 1 / 213
2024-12-23 13:28:38,902 - aiogram.event - INFO - Update id=166847927 is handled. Duration 158 ms by bot id=7101171025
2024-12-23 13:28:54,479 - telegram_bot.core.websocket_request - INFO - Message sent to websocket: 9 / 1 / 123
2024-12-23 13:28:54,708 - aiogram.event - INFO - Update id=166847928 is handled. Duration 237 ms by bot id=7101171025
2024-12-23 13:29:47,053 - telegram_bot.core.websocket_request - INFO - Message sent to websocket: 9 / 1 / 123
2024-12-23 13:29:47,327 - aiogram.event - INFO - Update id=166847929 is handled. Duration 283 ms by bot id=7101171025
2024-12-23 13:29:52,047 - telegram_bot.core.websocket_request - INFO - Message sent to websocket: 9 / 1 / 123
2024-12-23 13:29:52,317 - aiogram.event - INFO - Update id=166847930 is handled. Duration 279 ms by bot id=7101171025
2024-12-23 13:30:12,438 - telegram_bot.core.websocket_request - ERROR - ##################################################
2024-12-23 13:30:12,438 - telegram_bot.core.websocket_request - ERROR - Send to websocket: Cannot connect to host 127.0.0.1:8000 ssl:default [Connect call failed ('127.0.0.1', 8000)]
2024-12-23 13:30:12,438 - telegram_bot.core.websocket_request - ERROR - Traceback (most recent call last):
  File "/home/bybr/Desktop/english_bot/.venv/lib/python3.12/site-packages/aiohttp/connector.py", line 1109, in _wrap_create_connection
    sock = await aiohappyeyeballs.start_connection(
           ^^^^^^^^^^^^^^^^^^^^^^^^^^^^^^^^^^^^^^^^
  File "/home/bybr/Desktop/english_bot/.venv/lib/python3.12/site-packages/aiohappyeyeballs/impl.py", line 104, in start_connection
    raise first_exception
  File "/home/bybr/Desktop/english_bot/.venv/lib/python3.12/site-packages/aiohappyeyeballs/impl.py", line 82, in start_connection
    sock = await _connect_sock(
           ^^^^^^^^^^^^^^^^^^^^
  File "/home/bybr/Desktop/english_bot/.venv/lib/python3.12/site-packages/aiohappyeyeballs/impl.py", line 174, in _connect_sock
    await loop.sock_connect(sock, address)
  File "/usr/lib/python3.12/asyncio/selector_events.py", line 651, in sock_connect
    return await fut
           ^^^^^^^^^
  File "/usr/lib/python3.12/asyncio/selector_events.py", line 691, in _sock_connect_cb
    raise OSError(err, f'Connect call failed {address}')
ConnectionRefusedError: [Errno 111] Connect call failed ('127.0.0.1', 8000)

The above exception was the direct cause of the following exception:

Traceback (most recent call last):
  File "/home/bybr/Desktop/english_bot/telegram_bot/core/websocket_request.py", line 17, in send_to_websocket
    async with session.ws_connect(f"ws://{domain}/ws/chat/{chat_id}/") as ws:
  File "/home/bybr/Desktop/english_bot/.venv/lib/python3.12/site-packages/aiohttp/client.py", line 1360, in __aenter__
    self._resp: _RetType = await self._coro
                           ^^^^^^^^^^^^^^^^
  File "/home/bybr/Desktop/english_bot/.venv/lib/python3.12/site-packages/aiohttp/client.py", line 938, in _ws_connect
    resp = await self.request(
           ^^^^^^^^^^^^^^^^^^^
  File "/home/bybr/Desktop/english_bot/.venv/lib/python3.12/site-packages/aiohttp/client.py", line 663, in _request
    conn = await self._connector.connect(
           ^^^^^^^^^^^^^^^^^^^^^^^^^^^^^^
  File "/home/bybr/Desktop/english_bot/.venv/lib/python3.12/site-packages/aiohttp/connector.py", line 538, in connect
    proto = await self._create_connection(req, traces, timeout)
            ^^^^^^^^^^^^^^^^^^^^^^^^^^^^^^^^^^^^^^^^^^^^^^^^^^^
  File "/home/bybr/Desktop/english_bot/.venv/lib/python3.12/site-packages/aiohttp/connector.py", line 1050, in _create_connection
    _, proto = await self._create_direct_connection(req, traces, timeout)
               ^^^^^^^^^^^^^^^^^^^^^^^^^^^^^^^^^^^^^^^^^^^^^^^^^^^^^^^^^^
  File "/home/bybr/Desktop/english_bot/.venv/lib/python3.12/site-packages/aiohttp/connector.py", line 1384, in _create_direct_connection
    raise last_exc
  File "/home/bybr/Desktop/english_bot/.venv/lib/python3.12/site-packages/aiohttp/connector.py", line 1353, in _create_direct_connection
    transp, proto = await self._wrap_create_connection(
                    ^^^^^^^^^^^^^^^^^^^^^^^^^^^^^^^^^^^
  File "/home/bybr/Desktop/english_bot/.venv/lib/python3.12/site-packages/aiohttp/connector.py", line 1124, in _wrap_create_connection
    raise client_error(req.connection_key, exc) from exc
aiohttp.client_exceptions.ClientConnectorError: Cannot connect to host 127.0.0.1:8000 ssl:default [Connect call failed ('127.0.0.1', 8000)]

2024-12-23 13:30:12,438 - telegram_bot.core.websocket_request - ERROR - ##################################################
2024-12-23 13:30:12,622 - aiogram.event - INFO - Update id=166847931 is handled. Duration 186 ms by bot id=7101171025
2024-12-23 13:30:13,568 - telegram_bot.core.websocket_request - INFO - Message sent to websocket: 9 / 1 / 123
2024-12-23 13:30:13,629 - aiogram.event - INFO - Update id=166847932 is handled. Duration 69 ms by bot id=7101171025
2024-12-23 13:32:11,397 - telegram_bot.core.websocket_request - INFO - Message sent to websocket: 9 / 1 / test
2024-12-23 13:32:11,673 - aiogram.event - INFO - Update id=166847933 is handled. Duration 279 ms by bot id=7101171025
2024-12-23 13:34:06,710 - telegram_bot.core.websocket_request - INFO - Message sent to websocket: 9 / 1 / 123
2024-12-23 13:34:06,902 - aiogram.event - INFO - Update id=166847934 is handled. Duration 195 ms by bot id=7101171025
2024-12-23 13:34:22,071 - telegram_bot.core.websocket_request - INFO - Message sent to websocket: 9 / 1 / 123
2024-12-23 13:34:22,323 - aiogram.event - INFO - Update id=166847935 is handled. Duration 255 ms by bot id=7101171025
2024-12-23 13:34:25,557 - telegram_bot.core.websocket_request - INFO - Message sent to websocket: 9 / 1 / test
2024-12-23 13:34:25,729 - aiogram.event - INFO - Update id=166847936 is handled. Duration 175 ms by bot id=7101171025
2024-12-23 13:35:15,555 - telegram_bot.core.websocket_request - INFO - Message sent to websocket: 9 / 1 / 123
2024-12-23 13:35:15,722 - aiogram.event - INFO - Update id=166847937 is handled. Duration 171 ms by bot id=7101171025
2024-12-23 13:55:02,929 - aiogram.dispatcher - WARNING - Received SIGINT signal
2024-12-23 13:55:02,930 - aiogram.dispatcher - INFO - Polling stopped for bot @dofgd345borbot id=7101171025 - 'bobr123'
2024-12-23 13:55:02,930 - aiogram.dispatcher - INFO - Polling stopped
2024-12-23 13:55:06,819 - aiogram.dispatcher - INFO - Start polling
2024-12-23 13:55:06,855 - aiogram.dispatcher - INFO - Run polling for bot @dofgd345borbot id=7101171025 - 'bobr123'
2024-12-23 13:55:15,756 - aiogram.event - INFO - Update id=166847938 is handled. Duration 185 ms by bot id=7101171025
2024-12-23 13:55:24,223 - telegram_bot.core.websocket_request - INFO - Message sent to websocket: 9 / 1 / 123
2024-12-23 13:55:24,325 - aiogram.event - INFO - Update id=166847939 is handled. Duration 113 ms by bot id=7101171025
2024-12-23 13:59:10,208 - telegram_bot.core.websocket_request - INFO - Message sent to websocket: 9 / 1 / 123
2024-12-23 13:59:10,461 - aiogram.event - INFO - Update id=166847940 is handled. Duration 261 ms by bot id=7101171025
2024-12-23 13:59:23,684 - telegram_bot.core.websocket_request - INFO - Message sent to websocket: 9 / 1 / 123
2024-12-23 13:59:23,792 - aiogram.event - INFO - Update id=166847941 is handled. Duration 115 ms by bot id=7101171025
2024-12-23 14:00:39,792 - telegram_bot.core.websocket_request - INFO - Message sent to websocket: 9 / 1 / 123
2024-12-23 14:00:40,076 - aiogram.event - INFO - Update id=166847942 is handled. Duration 287 ms by bot id=7101171025
2024-12-23 14:00:42,484 - telegram_bot.core.websocket_request - INFO - Message sent to websocket: 9 / 1 / test
2024-12-23 14:00:42,615 - aiogram.event - INFO - Update id=166847943 is handled. Duration 134 ms by bot id=7101171025
2024-12-23 14:03:11,637 - telegram_bot.core.websocket_request - INFO - Message sent to websocket: 9 / 1 / 123
2024-12-23 14:03:11,920 - aiogram.event - INFO - Update id=166847944 is handled. Duration 291 ms by bot id=7101171025
2024-12-23 14:03:25,052 - telegram_bot.core.websocket_request - INFO - Message sent to websocket: 9 / 1 / 123
2024-12-23 14:03:25,115 - aiogram.event - INFO - Update id=166847945 is handled. Duration 72 ms by bot id=7101171025
2024-12-23 14:03:26,355 - telegram_bot.core.websocket_request - INFO - Message sent to websocket: 9 / 1 / 123
2024-12-23 14:03:26,441 - aiogram.event - INFO - Update id=166847946 is handled. Duration 89 ms by bot id=7101171025
2024-12-23 14:03:27,827 - telegram_bot.core.websocket_request - INFO - Message sent to websocket: 9 / 1 / 13
2024-12-23 14:03:27,926 - aiogram.event - INFO - Update id=166847947 is handled. Duration 103 ms by bot id=7101171025
2024-12-23 14:03:33,386 - telegram_bot.core.websocket_request - ERROR - ##################################################
2024-12-23 14:03:33,386 - telegram_bot.core.websocket_request - ERROR - Send to websocket: Cannot connect to host 127.0.0.1:8000 ssl:default [Connect call failed ('127.0.0.1', 8000)]
2024-12-23 14:03:33,387 - telegram_bot.core.websocket_request - ERROR - Traceback (most recent call last):
  File "/home/bybr/Desktop/english_bot/.venv/lib/python3.12/site-packages/aiohttp/connector.py", line 1109, in _wrap_create_connection
    sock = await aiohappyeyeballs.start_connection(
           ^^^^^^^^^^^^^^^^^^^^^^^^^^^^^^^^^^^^^^^^
  File "/home/bybr/Desktop/english_bot/.venv/lib/python3.12/site-packages/aiohappyeyeballs/impl.py", line 104, in start_connection
    raise first_exception
  File "/home/bybr/Desktop/english_bot/.venv/lib/python3.12/site-packages/aiohappyeyeballs/impl.py", line 82, in start_connection
    sock = await _connect_sock(
           ^^^^^^^^^^^^^^^^^^^^
  File "/home/bybr/Desktop/english_bot/.venv/lib/python3.12/site-packages/aiohappyeyeballs/impl.py", line 174, in _connect_sock
    await loop.sock_connect(sock, address)
  File "/usr/lib/python3.12/asyncio/selector_events.py", line 651, in sock_connect
    return await fut
           ^^^^^^^^^
  File "/usr/lib/python3.12/asyncio/selector_events.py", line 691, in _sock_connect_cb
    raise OSError(err, f'Connect call failed {address}')
ConnectionRefusedError: [Errno 111] Connect call failed ('127.0.0.1', 8000)

The above exception was the direct cause of the following exception:

Traceback (most recent call last):
  File "/home/bybr/Desktop/english_bot/telegram_bot/core/websocket_request.py", line 17, in send_to_websocket
    async with session.ws_connect(f"ws://{domain}/ws/chat/{chat_id}/") as ws:
  File "/home/bybr/Desktop/english_bot/.venv/lib/python3.12/site-packages/aiohttp/client.py", line 1360, in __aenter__
    self._resp: _RetType = await self._coro
                           ^^^^^^^^^^^^^^^^
  File "/home/bybr/Desktop/english_bot/.venv/lib/python3.12/site-packages/aiohttp/client.py", line 938, in _ws_connect
    resp = await self.request(
           ^^^^^^^^^^^^^^^^^^^
  File "/home/bybr/Desktop/english_bot/.venv/lib/python3.12/site-packages/aiohttp/client.py", line 663, in _request
    conn = await self._connector.connect(
           ^^^^^^^^^^^^^^^^^^^^^^^^^^^^^^
  File "/home/bybr/Desktop/english_bot/.venv/lib/python3.12/site-packages/aiohttp/connector.py", line 538, in connect
    proto = await self._create_connection(req, traces, timeout)
            ^^^^^^^^^^^^^^^^^^^^^^^^^^^^^^^^^^^^^^^^^^^^^^^^^^^
  File "/home/bybr/Desktop/english_bot/.venv/lib/python3.12/site-packages/aiohttp/connector.py", line 1050, in _create_connection
    _, proto = await self._create_direct_connection(req, traces, timeout)
               ^^^^^^^^^^^^^^^^^^^^^^^^^^^^^^^^^^^^^^^^^^^^^^^^^^^^^^^^^^
  File "/home/bybr/Desktop/english_bot/.venv/lib/python3.12/site-packages/aiohttp/connector.py", line 1384, in _create_direct_connection
    raise last_exc
  File "/home/bybr/Desktop/english_bot/.venv/lib/python3.12/site-packages/aiohttp/connector.py", line 1353, in _create_direct_connection
    transp, proto = await self._wrap_create_connection(
                    ^^^^^^^^^^^^^^^^^^^^^^^^^^^^^^^^^^^
  File "/home/bybr/Desktop/english_bot/.venv/lib/python3.12/site-packages/aiohttp/connector.py", line 1124, in _wrap_create_connection
    raise client_error(req.connection_key, exc) from exc
aiohttp.client_exceptions.ClientConnectorError: Cannot connect to host 127.0.0.1:8000 ssl:default [Connect call failed ('127.0.0.1', 8000)]

2024-12-23 14:03:33,387 - telegram_bot.core.websocket_request - ERROR - ##################################################
2024-12-23 14:03:33,840 - aiogram.event - INFO - Update id=166847948 is handled. Duration 549 ms by bot id=7101171025
2024-12-23 14:03:35,043 - telegram_bot.core.websocket_request - ERROR - ##################################################
2024-12-23 14:03:35,043 - telegram_bot.core.websocket_request - ERROR - Send to websocket: Cannot connect to host 127.0.0.1:8000 ssl:default [Connect call failed ('127.0.0.1', 8000)]
2024-12-23 14:03:35,044 - telegram_bot.core.websocket_request - ERROR - Traceback (most recent call last):
  File "/home/bybr/Desktop/english_bot/.venv/lib/python3.12/site-packages/aiohttp/connector.py", line 1109, in _wrap_create_connection
    sock = await aiohappyeyeballs.start_connection(
           ^^^^^^^^^^^^^^^^^^^^^^^^^^^^^^^^^^^^^^^^
  File "/home/bybr/Desktop/english_bot/.venv/lib/python3.12/site-packages/aiohappyeyeballs/impl.py", line 104, in start_connection
    raise first_exception
  File "/home/bybr/Desktop/english_bot/.venv/lib/python3.12/site-packages/aiohappyeyeballs/impl.py", line 82, in start_connection
    sock = await _connect_sock(
           ^^^^^^^^^^^^^^^^^^^^
  File "/home/bybr/Desktop/english_bot/.venv/lib/python3.12/site-packages/aiohappyeyeballs/impl.py", line 174, in _connect_sock
    await loop.sock_connect(sock, address)
  File "/usr/lib/python3.12/asyncio/selector_events.py", line 651, in sock_connect
    return await fut
           ^^^^^^^^^
  File "/usr/lib/python3.12/asyncio/selector_events.py", line 691, in _sock_connect_cb
    raise OSError(err, f'Connect call failed {address}')
ConnectionRefusedError: [Errno 111] Connect call failed ('127.0.0.1', 8000)

The above exception was the direct cause of the following exception:

Traceback (most recent call last):
  File "/home/bybr/Desktop/english_bot/telegram_bot/core/websocket_request.py", line 17, in send_to_websocket
    async with session.ws_connect(f"ws://{domain}/ws/chat/{chat_id}/") as ws:
  File "/home/bybr/Desktop/english_bot/.venv/lib/python3.12/site-packages/aiohttp/client.py", line 1360, in __aenter__
    self._resp: _RetType = await self._coro
                           ^^^^^^^^^^^^^^^^
  File "/home/bybr/Desktop/english_bot/.venv/lib/python3.12/site-packages/aiohttp/client.py", line 938, in _ws_connect
    resp = await self.request(
           ^^^^^^^^^^^^^^^^^^^
  File "/home/bybr/Desktop/english_bot/.venv/lib/python3.12/site-packages/aiohttp/client.py", line 663, in _request
    conn = await self._connector.connect(
           ^^^^^^^^^^^^^^^^^^^^^^^^^^^^^^
  File "/home/bybr/Desktop/english_bot/.venv/lib/python3.12/site-packages/aiohttp/connector.py", line 538, in connect
    proto = await self._create_connection(req, traces, timeout)
            ^^^^^^^^^^^^^^^^^^^^^^^^^^^^^^^^^^^^^^^^^^^^^^^^^^^
  File "/home/bybr/Desktop/english_bot/.venv/lib/python3.12/site-packages/aiohttp/connector.py", line 1050, in _create_connection
    _, proto = await self._create_direct_connection(req, traces, timeout)
               ^^^^^^^^^^^^^^^^^^^^^^^^^^^^^^^^^^^^^^^^^^^^^^^^^^^^^^^^^^
  File "/home/bybr/Desktop/english_bot/.venv/lib/python3.12/site-packages/aiohttp/connector.py", line 1384, in _create_direct_connection
    raise last_exc
  File "/home/bybr/Desktop/english_bot/.venv/lib/python3.12/site-packages/aiohttp/connector.py", line 1353, in _create_direct_connection
    transp, proto = await self._wrap_create_connection(
                    ^^^^^^^^^^^^^^^^^^^^^^^^^^^^^^^^^^^
  File "/home/bybr/Desktop/english_bot/.venv/lib/python3.12/site-packages/aiohttp/connector.py", line 1124, in _wrap_create_connection
    raise client_error(req.connection_key, exc) from exc
aiohttp.client_exceptions.ClientConnectorError: Cannot connect to host 127.0.0.1:8000 ssl:default [Connect call failed ('127.0.0.1', 8000)]

2024-12-23 14:03:35,044 - telegram_bot.core.websocket_request - ERROR - ##################################################
2024-12-23 14:03:35,248 - aiogram.event - INFO - Update id=166847949 is handled. Duration 206 ms by bot id=7101171025
2024-12-23 14:03:36,970 - telegram_bot.core.websocket_request - INFO - Message sent to websocket: 9 / 1 / 34
2024-12-23 14:03:37,049 - aiogram.event - INFO - Update id=166847950 is handled. Duration 86 ms by bot id=7101171025
2024-12-23 14:04:32,698 - aiogram.dispatcher - WARNING - Received SIGINT signal
2024-12-23 14:04:32,699 - aiogram.dispatcher - INFO - Polling stopped for bot @dofgd345borbot id=7101171025 - 'bobr123'
2024-12-23 14:04:32,699 - aiogram.dispatcher - INFO - Polling stopped
2024-12-23 14:04:35,561 - aiogram.dispatcher - INFO - Start polling
2024-12-23 14:04:35,597 - aiogram.dispatcher - INFO - Run polling for bot @dofgd345borbot id=7101171025 - 'bobr123'
2024-12-23 14:04:36,902 - aiogram.event - INFO - Update id=166847951 is not handled. Duration 0 ms by bot id=7101171025
2024-12-23 14:04:40,423 - aiogram.event - INFO - Update id=166847952 is handled. Duration 318 ms by bot id=7101171025
2024-12-23 14:04:41,556 - telegram_bot.core.websocket_request - INFO - Message sent to websocket: 9 / 1 / test
2024-12-23 14:04:41,680 - aiogram.event - INFO - Update id=166847953 is handled. Duration 133 ms by bot id=7101171025
2024-12-23 14:09:11,733 - aiogram.dispatcher - WARNING - Received SIGINT signal
2024-12-23 14:09:11,733 - aiogram.dispatcher - INFO - Polling stopped for bot @dofgd345borbot id=7101171025 - 'bobr123'
2024-12-23 14:09:11,733 - aiogram.dispatcher - INFO - Polling stopped
2024-12-23 14:09:15,064 - aiogram.dispatcher - INFO - Start polling
2024-12-23 14:09:15,103 - aiogram.dispatcher - INFO - Run polling for bot @dofgd345borbot id=7101171025 - 'bobr123'
2024-12-23 14:09:18,160 - aiogram.event - INFO - Update id=166847954 is not handled. Duration 0 ms by bot id=7101171025
2024-12-23 14:09:21,552 - aiogram.event - INFO - Update id=166847955 is handled. Duration 267 ms by bot id=7101171025
2024-12-23 14:09:22,509 - telegram_bot.core.db_request - ERROR - Get or create chat student and admin: Cannot resolve keyword 'telegram_user' into field. Choices are: admin_list, id, messages, student, student_id, teacher, teacher_id
2024-12-23 14:09:22,642 - aiogram.event - INFO - Update id=166847956 is handled. Duration 134 ms by bot id=7101171025
2024-12-23 14:10:02,340 - aiogram.dispatcher - WARNING - Received SIGINT signal
2024-12-23 14:10:02,340 - aiogram.dispatcher - INFO - Polling stopped for bot @dofgd345borbot id=7101171025 - 'bobr123'
2024-12-23 14:10:02,340 - aiogram.dispatcher - INFO - Polling stopped
2024-12-23 14:10:05,661 - aiogram.dispatcher - INFO - Start polling
2024-12-23 14:10:05,695 - aiogram.dispatcher - INFO - Run polling for bot @dofgd345borbot id=7101171025 - 'bobr123'
2024-12-23 14:10:09,591 - aiogram.event - INFO - Update id=166847957 is handled. Duration 208 ms by bot id=7101171025
2024-12-23 14:10:10,799 - telegram_bot.core.db_request - ERROR - Get or create chat student and admin: Cannot query "Telegram volody015": Must be "CustomUser" instance.
2024-12-23 14:10:10,884 - aiogram.event - INFO - Update id=166847958 is handled. Duration 86 ms by bot id=7101171025
2024-12-23 14:14:29,024 - aiogram.dispatcher - WARNING - Received SIGINT signal
2024-12-23 14:14:29,024 - aiogram.dispatcher - INFO - Polling stopped for bot @dofgd345borbot id=7101171025 - 'bobr123'
2024-12-23 14:14:29,024 - aiogram.dispatcher - INFO - Polling stopped
2024-12-23 14:14:32,091 - aiogram.dispatcher - INFO - Start polling
2024-12-23 14:14:32,135 - aiogram.dispatcher - INFO - Run polling for bot @dofgd345borbot id=7101171025 - 'bobr123'
2024-12-23 14:14:36,830 - aiogram.event - INFO - Update id=166847959 is handled. Duration 279 ms by bot id=7101171025
2024-12-23 14:14:38,017 - telegram_bot.core.websocket_request - INFO - Message sent to websocket: 1 / 1 / 123
2024-12-23 14:14:38,118 - aiogram.event - INFO - Update id=166847960 is handled. Duration 110 ms by bot id=7101171025
2024-12-23 14:14:52,478 - telegram_bot.core.websocket_request - INFO - Message sent to websocket: 9 / 1 / 235
2024-12-23 14:14:52,583 - aiogram.event - INFO - Update id=166847961 is handled. Duration 109 ms by bot id=7101171025
2024-12-23 14:15:23,444 - telegram_bot.core.websocket_request - INFO - Message sent to websocket: 9 / 1 / /teacher
2024-12-23 14:15:23,631 - aiogram.event - INFO - Update id=166847962 is handled. Duration 196 ms by bot id=7101171025
2024-12-23 14:15:24,399 - telegram_bot.core.websocket_request - INFO - Message sent to websocket: 9 / 1 / test
2024-12-23 14:15:24,473 - aiogram.event - INFO - Update id=166847963 is handled. Duration 78 ms by bot id=7101171025
2024-12-23 14:15:39,638 - telegram_bot.core.websocket_request - INFO - Message sent to websocket: 9 / 1 / /teacher
2024-12-23 14:15:39,835 - aiogram.event - INFO - Update id=166847964 is handled. Duration 201 ms by bot id=7101171025
2024-12-23 14:16:16,222 - aiogram.dispatcher - WARNING - Received SIGINT signal
2024-12-23 14:16:16,222 - aiogram.dispatcher - INFO - Polling stopped for bot @dofgd345borbot id=7101171025 - 'bobr123'
2024-12-23 14:16:16,222 - aiogram.dispatcher - INFO - Polling stopped
2024-12-23 14:16:19,135 - aiogram.dispatcher - INFO - Start polling
2024-12-23 14:16:19,176 - aiogram.dispatcher - INFO - Run polling for bot @dofgd345borbot id=7101171025 - 'bobr123'
2024-12-23 14:16:20,101 - aiogram.event - INFO - Update id=166847965 is handled. Duration 262 ms by bot id=7101171025
2024-12-23 14:16:27,469 - telegram_bot.core.websocket_request - INFO - Message sent to websocket: 1 / 1 / hello
2024-12-23 14:16:27,628 - aiogram.event - INFO - Update id=166847966 is handled. Duration 163 ms by bot id=7101171025
2024-12-23 14:18:45,836 - aiogram.dispatcher - WARNING - Received SIGINT signal
2024-12-23 14:18:45,836 - aiogram.dispatcher - INFO - Polling stopped for bot @dofgd345borbot id=7101171025 - 'bobr123'
2024-12-23 14:18:45,836 - aiogram.dispatcher - INFO - Polling stopped
2024-12-23 14:18:48,873 - aiogram.dispatcher - INFO - Start polling
2024-12-23 14:18:48,960 - aiogram.dispatcher - INFO - Run polling for bot @dofgd345borbot id=7101171025 - 'bobr123'
2024-12-23 14:19:05,535 - aiogram.event - INFO - Update id=166847967 is handled. Duration 245 ms by bot id=7101171025
2024-12-23 14:19:07,392 - telegram_bot.core.websocket_request - INFO - Message sent to websocket: 1 / 1 / test
2024-12-23 14:19:07,541 - aiogram.event - INFO - Update id=166847968 is handled. Duration 153 ms by bot id=7101171025
2024-12-23 14:19:32,860 - aiogram.event - INFO - Update id=166847969 is handled. Duration 244 ms by bot id=7101171025
2024-12-23 14:19:35,103 - telegram_bot.core.websocket_request - INFO - Message sent to websocket: 9 / 1 / 123
2024-12-23 14:19:35,259 - aiogram.event - INFO - Update id=166847970 is handled. Duration 159 ms by bot id=7101171025
